Workbook

Sheet Pricing
A1: Input market data
A2: Instrument | B2: Years | C2: Quote | D2: Model | E2: PV01 / million | G2: // Assumptions:
A3: 3M Fixing | B3: 0.25 | C3: 0.0253 | D3: {=TRANSPOSE(Bootstrap!A308:H308)} -> 0.0253 | E3: 24.842252 | G3: // All swaps are quarterly 3M-Euribor (floating leg) versus annual coupon (fixed leg). This is market convention for Euribor swaps.
A4: 1Y Swap | B4: 1 | C4: 0.0232 | D4: 0.0232 | E4: 97.723053 | G4: // All coupon periods are exactly 1/4 of a year. We ignore intricansies of the Gregorian calendar.
A5: 2Y Swap | B5: 2 | C5: 0.0229 | D5: 0.0229 | E5: 193.287 | G5: // Underlying model is a cubic spline of expected Euribor fixings
A6: 3Y Swap | B6: 3 | C6: 0.0236 | D6: 0.0236 | E6: 286.51548 | G6: // A 1-year swap includes fixings at times 0, 0.25, 0.5 and 0.75, so it will be adding x=0.75 as a spline node
A7: 4Y Swap | B7: 4 | C7: 0.0242 | D7: 0.0242 | E7: 329.0742 | G7: // Each segment of the spine is given by a*x^3 + b*x^2 + c*c + d
A8: 5Y Swap | B8: 5 | C8: 0.0248 | D8: 0.0248 | E8: 465.81144 | G8: // A cubic spline tries to match values on the end of the segment, as well as two derivatives
A9: 7Y Swap | B9: 7 | C9: 0.0257 | D9: 0.0257 | E9: 635.46978 | G9: // Target value for a derivative at interior points is an average of secants
A10: 10Y Swap | B10: 10 | C10: 0.0269 | D10: 0.0269 | E10: 872.1977 | G10: // To help with monotonicity, we set derivatives to zero in case slopes on the left and on the right have opposite signs
A12: Continously compounded yield & pricing a swap
B13: Spline Coefficients | L13: Buyer's | M13: Buyer's
A14: Years | B14: a | C14: b | D14: c | E14: d | G14: Swap Start | H14: 2.5 | I14: (years) | K14: Instrument | L14: PV01 | M14: Hedge Notional
A15: =Bootstrap!A298 -> 0 | B15: =Bootstrap!H298 -> 0.021795525 | C15: =Bootstrap!I298 -> -0.024519965 | D15: =Bootstrap!J298 -> 0 | E15: =Bootstrap!K298 -> 0.0253 | G15: Swap End | H15: 5 | I15: (years) | K15: =A3 -> 3M Fixing | L15: -15.760438 | M15: =-L15/E3*1000000 -> 634420.68
A16: =Bootstrap!A299 -> 0.75 | B16: =Bootstrap!H299 -> -0.0037060713 | C16: =Bootstrap!I299 -> 0.015057783 | D16: =Bootstrap!J299 -> -0.016332679 | E16: =Bootstrap!K299 -> 0.026045512 | G16: Fixed Freq | H16: 2 | I16: (1=annually, 2=semi, 4=quarterly) | K16: =A4 -> 1Y Swap | L16: 64.439762 | M16: =-L16/E4*1000000 -> -659412.08
A17: =Bootstrap!A300 -> 1.75 | B17: =Bootstrap!H300 -> 0.00027360595 | C17: =Bootstrap!I300 -> -0.0024030576 | D17: =Bootstrap!J300 -> 0.0082169775 | E17: =Bootstrap!K300 -> 0.015228854 | G17: Notional | H17: 1000000 | K17: =A5 -> 2Y Swap | L17: -195.77212 | M17: =-L17/E5*1000000 -> 1012857.2
A18: =Bootstrap!A301 -> 2.75 | B18: =Bootstrap!H301 -> 0.00076954098 | C18: =Bootstrap!I301 -> -0.0075376686 | D18: =Bootstrap!J301 -> 0.025205812 | E18: =Bootstrap!K301 -> -0.0029738436 | G18: Swap Rate | H18: 0.026277855 | K18: =A6 -> 3Y Swap | L18: -112.87181 | M18: =-L18/E6*1000000 -> 393946.63
A19: =Bootstrap!A302 -> 3.75 | B19: =Bootstrap!H302 -> -0.00099382573 | C19: =Bootstrap!I302 -> 0.012524492 | D19: =Bootstrap!J302 -> -0.050868357 | E19: =Bootstrap!K302 -> 0.093170202 | K19: =A7 -> 4Y Swap | L19: -39.632179 | M19: =-L19/E7*1000000 -> 120435.39
A20: =Bootstrap!A303 -> 4.75 | B20: =Bootstrap!H303 -> 0.00027148645 | C20: =Bootstrap!I303 -> -0.0047335044 | D20: =Bootstrap!J303 -> 0.027436787 | E20: =Bootstrap!K303 -> -0.025001577 | G20: Buyer PV | H20: =SUM(I26:I66)-SUM(J26:J66) -> 0 | K20: =A8 -> 5Y Swap | L20: 462.84905 | M20: =-L20/E8*1000000 -> -993640.37
A21: =Bootstrap!A304 -> 6.75 | B21: =Bootstrap!H304 -> -0.00010944565 | C21: =Bootstrap!I304 -> 0.002692027 | D21: =Bootstrap!J304 -> -0.020739229 | E21: =Bootstrap!K304 -> 0.07901524 | G21: Seller PV | H21: =-H20 -> 0 | K21: =A9 -> 7Y Swap | L21: -0.024887871 | M21: =-L21/E9*1000000 -> 39.164523
A22: =Bootstrap!A305 -> 9.75 | B22: =Bootstrap!H305 -> 6.6637222e-08 | C22: =Bootstrap!I305 -> -1.3977157e-05 | D22: =Bootstrap!J305 -> 0.0007963148 | E22: =Bootstrap!K305 -> 0.02478071 | G22: Fair Swap | H22: =H18 * SUM(I27:I66)/SUM(J27:J66) -> 0.026277855 | K22: =A10 -> 10Y Swap | L22: -0.00099093842 | M22: =-L22/E10*1000000 -> 1.1361397
L23: =SUM(L15:L22) -> 163.22639 | M23: =SUM(M15:M22) -> 508647.71
A25: Years | B25: Left X | C25: a | D25: b | E25: c | F25: d | G25: Euribor | H25: Disc Fact | I25: Float PV | J25: Fixed PV
A26: 0 | B26: {=INDEX(A15:A23, MATCH(A26:A66, A15:A23, 1))} -> 0 | C26: {=VLOOKUP(B26:B66, A15:E22, COLUMN(B15)-COLUMN(A15)+1, FALSE)} -> 0.021795525 | D26: {=VLOOKUP(B26:B66, A15:E22, COLUMN(C15)-COLUMN(A15)+1, FALSE)} -> -0.024519965 | E26: {=VLOOKUP(B26:B66, A15:E22, COLUMN(D15)-COLUMN(A15)+1, FALSE)} -> 0 | F26: {=VLOOKUP(B26:B66, A15:E22, COLUMN(E15)-COLUMN(A15)+1, FALSE)} -> 0.0253 | G26: =C26*A26^3 + D26*A26^2 + E26*A26 + F26 -> 0.0253 | H26: 1
A27: 0.25 | B27: 0 | C27: 0.021795525 | D27: -0.024519965 | E27: 0 | F27: 0.0253 | G27: =C27*A27^3 + D27*A27^2 + E27*A27 + F27 -> 0.024108057 | H27: =H26 / (1 + G26*(A27-A26)) -> 0.99371475 | I27: {=(A27:A66 <= H15) * (A27:A66 > H14) * G26:G65 * H27:H66 * (A27:A66-A26:A65) * H17} -> 0 | J27: {=(A27:A66 <= H15) * (A27:A66 > H14) * (ROUND((H14+A27:A66)*H16, 0)=(H14+A27:A66)*H16) * H27:H66 * H17 * H18 / H16} -> 0
A28: 0.5 | B28: 0 | C28: 0.021795525 | D28: -0.024519965 | E28: 0 | F28: 0.0253 | G28: =C28*A28^3 + D28*A28^2 + E28*A28 + F28 -> 0.021894449 | H28: =H27 / (1 + G27*(A28-A27)) -> 0.9877615 | I28: 0 | J28: 0
A29: 0.75 | B29: 0.75 | C29: -0.0037060713 | D29: 0.015057783 | E29: -0.016332679 | F29: 0.026045512 | G29: =C29*A29^3 + D29*A29^2 + E29*A29 + F29 -> 0.020702506 | H29: =H28 / (1 + G28*(A29-A28)) -> 0.98238431 | I29: 0 | J29: 0
A30: 1 | B30: 0.75 | C30: -0.0037060713 | D30: 0.015057783 | E30: -0.016332679 | F30: 0.026045512 | G30: =C30*A30^3 + D30*A30^2 + E30*A30 + F30 -> 0.021064544 | H30: =H29 / (1 + G29*(A30-A29)) -> 0.97732604 | I30: 0 | J30: 0
A31: 1.25 | B31: 0.75 | C31: -0.0037060713 | D31: 0.015057783 | E31: -0.016332679 | F31: 0.026045512 | G31: =C31*A31^3 + D31*A31^2 + E31*A31 + F31 -> 0.021919028 | H31: =H30 / (1 + G30*(A31-A30)) -> 0.97220627 | I31: 0 | J31: 0
A32: 1.5 | B32: 0.75 | C32: -0.0037060713 | D32: 0.015057783 | E32: -0.016332679 | F32: 0.026045512 | G32: =C32*A32^3 + D32*A32^2 + E32*A32 + F32 -> 0.022918514 | H32: =H31 / (1 + G31*(A32-A31)) -> 0.96690785 | I32: 0 | J32: 0
A33: 1.75 | B33: 1.75 | C33: 0.00027360595 | D33: -0.0024030576 | E33: 0.0082169775 | F33: 0.015228854 | G33: =C33*A33^3 + D33*A33^2 + E33*A33 + F33 -> 0.023715557 | H33: =H32 / (1 + G32*(A33-A32)) -> 0.96139938 | I33: 0 | J33: 0
A34: 2 | B34: 1.75 | C34: 0.00027360595 | D34: -0.0024030576 | E34: 0.0082169775 | F34: 0.015228854 | G34: =C34*A34^3 + D34*A34^2 + E34*A34 + F34 -> 0.024239426 | H34: =H33 / (1 + G33*(A34-A33)) -> 0.95573295 | I34: 0 | J34: 0
A35: 2.25 | B35: 1.75 | C35: 0.00027360595 | D35: -0.0024030576 | E35: 0.0082169775 | F35: 0.015228854 | G35: =C35*A35^3 + D35*A35^2 + E35*A35 + F35 -> 0.024668117 | H35: =H34 / (1 + G34*(A35-A34)) -> 0.94997623 | I35: 0 | J35: 0
A36: 2.5 | B36: 1.75 | C36: 0.00027360595 | D36: -0.0024030576 | E36: 0.0082169775 | F36: 0.015228854 | G36: =C36*A36^3 + D36*A36^2 + E36*A36 + F36 -> 0.02502728 | H36: =H35 / (1 + G35*(A36-A35)) -> 0.94415361 | I36: 0 | J36: 0
A37: 2.75 | B37: 2.75 | C37: 0.00076954098 | D37: -0.0075376686 | E37: 0.025205812 | F37: -0.0029738436 | G37: =C37*A37^3 + D37*A37^2 + E37*A37 + F37 -> 0.025342567 | H37: =H36 / (1 + G36*(A37-A36)) -> 0.93828294 | I37: 5870.6675 | J37: 0
A38: 3 | B38: 2.75 | C38: 0.00076954098 | D38: -0.0075376686 | E38: 0.025205812 | F38: -0.0029738436 | G38: =C38*A38^3 + D38*A38^2 + E38*A38 + F38 -> 0.025582181 | H38: =H37 / (1 + G37*(A38-A37)) -> 0.93237574 | I38: 5907.1988 | J38: 12250.417
A39: 3.25 | B39: 2.75 | C39: 0.00076954098 | D39: -0.0075376686 | E39: 0.025205812 | F39: -0.0029738436 | G39: =C39*A39^3 + D39*A39^2 + E39*A39 + F39 -> 0.025745319 | H39: =H38 / (1 + G38*(A39-A38)) -> 0.92645058 | I39: 5925.1565 | J39: 0
... A65: 9.75 | B65: 9.75 | C65: 6.6637222e-08 | D65: -1.3977157e-05 | E65: 0.0007963148 | F65: 0.02478071 | G65: =C65*A65^3 + D65*A65^2 + E65*A65 + F65 -> 0.03127784 | H65: =H64 / (1 + G64*(A65-A64)) -> 0.77132731 | I65: 0 | J65: 0
A66: 10 | B66: 9.75 | C66: 6.6637222e-08 | D66: -1.3977157e-05 | E66: 0.0007963148 | F66: 0.02478071 | H66: =H65 / (1 + G65*(A66-A65)) -> 0.76534275 | I66: 0 | J66: 0

Sheet Bootstrap
A1: Instrument | B1: Quote | C1: Maturity in Years | E1: // Bump ("shock") for the numerical estimation | J1: =Pricing!G2 -> // Assumptions:
A2: =Pricing!A3 -> 3M Fixing | B2: =Pricing!C3 -> 0.0253 | C2: =Pricing!B3 -> 0.25 | E2: // of the dertivative in the Newton method | J2: // All swaps are quarterly 3M-Euribor (floating leg) versus annual coupon (fixed leg). This is market convention for Euribor swaps.
A3: =Pricing!A4 -> 1Y Swap | B3: =Pricing!C4 -> 0.0232 | C3: =Pricing!B4 -> 1 | E3: Bump | F3: 0.0001 | J3: // All coupon periods are exactly 1/4 of a year. We ignore intricansies of the Gregorian calendar.
A4: =Pricing!A5 -> 2Y Swap | B4: =Pricing!C5 -> 0.0229 | C4: =Pricing!B5 -> 2 | J4: // Underlying model is a cubic spline of expected Euribor fixings
A5: =Pricing!A6 -> 3Y Swap | B5: =Pricing!C6 -> 0.0236 | C5: =Pricing!B6 -> 3 | E5: Monotonic | F5: TRUE | J5: // A 1-year swap includes fixings at times 0, 0.25, 0.5 and 0.75, so it will be adding x=0.75 as a spline node
A6: =Pricing!A7 -> 4Y Swap | B6: =Pricing!C7 -> 0.0242 | C6: =Pricing!B7 -> 4 | E6: Fixed Freq | F6: 1 | J6: // Each segment of the spine is given by a*x^3 + b*x^2 + c*c + d
A7: =Pricing!A8 -> 5Y Swap | B7: =Pricing!C8 -> 0.0248 | C7: =Pricing!B8 -> 5 | J7: // A cubic spline tries to match values on the end of the segment, as well as two derivatives
A8: =Pricing!A9 -> 7Y Swap | B8: =Pricing!C9 -> 0.0257 | C8: =Pricing!B9 -> 7 | J8: // Target value for a derivative at interior points is an average of secants
A9: =Pricing!A10 -> 10Y Swap | B9: =Pricing!C10 -> 0.0269 | C9: =Pricing!B10 -> 10 | J9: // To help with monotonicity, we set derivatives to zero in case slopes on the left and on the right have opposite signs
A11: 1. Initial guess | M11: 1a. Bump parameter #1 | Z11: 1b. Bump parameter #2 | AM11: 1c. Bump parameter #3 | AZ11: 1d. Bump parameter #4 | BM11: 1e. Bump parameter #5 | BZ11: 1f. Bump parameter #6 | CM11: 1g. Bump parameter #7 | CZ11: 1h. Bump parameter #8
A12: Left Boundary | C12: Right Boundary | E12: Slope | F12: Derivatives | H12: Spline Coefficients | M12: Bump | N12: Left Boundary | P12: Right Boundary | R12: Slope | S12: Derivatives | U12: Spline Coefficients | Z12: Bump | AA12: Left Boundary | AC12: Right Boundary | AE12: Slope | AF12: Derivatives | AH12: Spline Coefficients | AM12: Bump | AN12: Left Boundary | AP12: Right Boundary | AR12: Slope | AS12: Derivatives | AU12: Spline Coefficients | AZ12: Bump | BA12: Left Boundary | BC12: Right Boundary | BE12: Slope | BF12: Derivatives | BH12: Spline Coefficients | BM12: Bump | BN12: Left Boundary | BP12: Right Boundary | BR12: Slope | BS12: Derivatives | BU12: Spline Coefficients | BZ12: Bump | CA12: Left Boundary | CC12: Right Boundary | CE12: Slope | CF12: Derivatives | CH12: Spline Coefficients | CM12: Bump | CN12: Left Boundary | CP12: Right Boundary | CR12: Slope | CS12: Derivatives | CU12: Spline Coefficients | CZ12: Bump | DA12: Left Boundary | DC12: Right Boundary | DE12: Slope | DF12: Derivatives | DH12: Spline Coefficients
A13: Years | B13: Euribor | C13: Years | D13: Euribor | F13: Left | G13: Right | H13: a | I13: b | J13: c | K13: d | M13: =$F$3 -> 0.0001 | N13: Years | O13: Euribor | P13: Years | Q13: Euribor | S13: Left | T13: Right | U13: a | V13: b | W13: c | X13: d | Z13: =$F$3 -> 0.0001 | AA13: Years | AB13: Euribor | AC13: Years | AD13: Euribor | AF13: Left | AG13: Right | AH13: a | AI13: b | AJ13: c | AK13: d | AM13: =$F$3 -> 0.0001 | AN13: Years | AO13: Euribor | AP13: Years | AQ13: Euribor | AS13: Left | AT13: Right | AU13: a | AV13: b | AW13: c | AX13: d | AZ13: =$F$3 -> 0.0001 | BA13: Years | BB13: Euribor | BC13: Years | BD13: Euribor | BF13: Left | BG13: Right | BH13: a | BI13: b | BJ13: c | BK13: d | BM13: =$F$3 -> 0.0001 | BN13: Years | BO13: Euribor | BP13: Years | BQ13: Euribor | BS13: Left | BT13: Right | BU13: a | BV13: b | BW13: c | BX13: d | BZ13: =$F$3 -> 0.0001 | CA13: Years | CB13: Euribor | CC13: Years | CD13: Euribor | CF13: Left | CG13: Right | CH13: a | CI13: b | CJ13: c | CK13: d | CM13: =$F$3 -> 0.0001 | CN13: Years | CO13: Euribor | CP13: Years | CQ13: Euribor | CS13: Left | CT13: Right | CU13: a | CV13: b | CW13: c | CX13: d | CZ13: =$F$3 -> 0.0001 | DA13: Years | DB13: Euribor | DC13: Years | DD13: Euribor | DF13: Left | DG13: Right | DH13: a | DI13: b | DJ13: c | DK13: d
A14: =C2-0.25 -> 0 | B14: =B2 -> 0.0253 | C14: =A15 -> 0.75 | D14: =B15 -> 0.0211 | E14: =(D14-B14)/(C14-A14) -> -0.0056 | F14: 0 | G14: =IF($F$5, (E14*E15>=0) * AVERAGE(E14:E15), AVERAGE(E14:E15)) -> 0 | H14: =(F14+G14-2*(D14-B14)/(C14-A14))/(C14-A14)^2 -> 0.019911111 | I14: =((D14-B14)/(C14-A14) - F14 - H14*(C14^2 + A14*C14 - 2*A14^2))/(C14-A14) -> -0.0224 | J14: =F14-2*I14*A14 - 3*H14*A14^2 -> 0 | K14: =B14 -H14*A14^3 - I14*A14^2 - J14*A14 -> 0.0253 | N14: =$A14 -> 0 | O14: =$B14+M13 -> 0.0254 | P14: =N15 -> 0.75 | Q14: =O15 -> 0.0211 | R14: =(Q14-O14)/(P14-N14) -> -0.0057333333 | S14: 0 | T14: =IF($F$5, (R14*R15>=0) * AVERAGE(R14:R15), AVERAGE(R14:R15)) -> 0 | U14: =(S14+T14-2*(Q14-O14)/(P14-N14))/(P14-N14)^2 -> 0.020385185 | V14: =((Q14-O14)/(P14-N14) - S14 - U14*(P14^2 + N14*P14 - 2*N14^2))/(P14-N14) -> -0.022933333 | W14: =S14-2*V14*N14 - 3*U14*N14^2 -> 0 | X14: =O14 -U14*N14^3 - V14*N14^2 - W14*N14 -> 0.0254 | AA14: =$A14 -> 0 | AB14: =$B14 -> 0.0253 | AC14: =AA15 -> 0.75 | AD14: =AB15 -> 0.0212 | AE14: =(AD14-AB14)/(AC14-AA14) -> -0.0054666667 | AF14: 0 | AG14: =IF($F$5, (AE14*AE15>=0) * AVERAGE(AE14:AE15), AVERAGE(AE14:AE15)) -> 0 | AH14: =(AF14+AG14-2*(AD14-AB14)/(AC14-AA14))/(AC14-AA14)^2 -> 0.019437037 | AI14: =((AD14-AB14)/(AC14-AA14) - AF14 - AH14*(AC14^2 + AA14*AC14 - 2*AA14^2))/(AC14-AA14) -> -0.021866667 | AJ14: =AF14-2*AI14*AA14 - 3*AH14*AA14^2 -> 0 | AK14: =AB14 -AH14*AA14^3 - AI14*AA14^2 - AJ14*AA14 -> 0.0253 | AN14: =$A14 -> 0 | AO14: =$B14 -> 0.0253 | AP14: =AN15 -> 0.75 | AQ14: =AO15 -> 0.0211 | AR14: =(AQ14-AO14)/(AP14-AN14) -> -0.0056 | AS14: 0 | AT14: =IF($F$5, (AR14*AR15>=0) * AVERAGE(AR14:AR15), AVERAGE(AR14:AR15)) -> 0 | AU14: =(AS14+AT14-2*(AQ14-AO14)/(AP14-AN14))/(AP14-AN14)^2 -> 0.019911111 | AV14: =((AQ14-AO14)/(AP14-AN14) - AS14 - AU14*(AP14^2 + AN14*AP14 - 2*AN14^2))/(AP14-AN14) -> -0.0224 | AW14: =AS14-2*AV14*AN14 - 3*AU14*AN14^2 -> 0 | AX14: =AO14 -AU14*AN14^3 - AV14*AN14^2 - AW14*AN14 -> 0.0253 | BA14: =$A14 -> 0 | BB14: =$B14 -> 0.0253 | BC14: =BA15 -> 0.75 | BD14: =BB15 -> 0.0211 | BE14: =(BD14-BB14)/(BC14-BA14) -> -0.0056 | BF14: 0 | BG14: =IF($F$5, (BE14*BE15>=0) * AVERAGE(BE14:BE15), AVERAGE(BE14:BE15)) -> 0 | BH14: =(BF14+BG14-2*(BD14-BB14)/(BC14-BA14))/(BC14-BA14)^2 -> 0.019911111 | BI14: =((BD14-BB14)/(BC14-BA14) - BF14 - BH14*(BC14^2 + BA14*BC14 - 2*BA14^2))/(BC14-BA14) -> -0.0224 | BJ14: =BF14-2*BI14*BA14 - 3*BH14*BA14^2 -> 0 | BK14: =BB14 -BH14*BA14^3 - BI14*BA14^2 - BJ14*BA14 -> 0.0253 | BN14: =$A14 -> 0 | BO14: =$B14 -> 0.0253 | BP14: =BN15 -> 0.75 | BQ14: =BO15 -> 0.0211 | BR14: =(BQ14-BO14)/(BP14-BN14) -> -0.0056 | BS14: 0 | BT14: =IF($F$5, (BR14*BR15>=0) * AVERAGE(BR14:BR15), AVERAGE(BR14:BR15)) -> 0 | BU14: =(BS14+BT14-2*(BQ14-BO14)/(BP14-BN14))/(BP14-BN14)^2 -> 0.019911111 | BV14: =((BQ14-BO14)/(BP14-BN14) - BS14 - BU14*(BP14^2 + BN14*BP14 - 2*BN14^2))/(BP14-BN14) -> -0.0224 | BW14: =BS14-2*BV14*BN14 - 3*BU14*BN14^2 -> 0 | BX14: =BO14 -BU14*BN14^3 - BV14*BN14^2 - BW14*BN14 -> 0.0253 | CA14: =$A14 -> 0 | CB14: =$B14 -> 0.0253 | CC14: =CA15 -> 0.75 | CD14: =CB15 -> 0.0211 | CE14: =(CD14-CB14)/(CC14-CA14) -> -0.0056 | CF14: 0 | CG14: =IF($F$5, (CE14*CE15>=0) * AVERAGE(CE14:CE15), AVERAGE(CE14:CE15)) -> 0 | CH14: =(CF14+CG14-2*(CD14-CB14)/(CC14-CA14))/(CC14-CA14)^2 -> 0.019911111 | CI14: =((CD14-CB14)/(CC14-CA14) - CF14 - CH14*(CC14^2 + CA14*CC14 - 2*CA14^2))/(CC14-CA14) -> -0.0224 | CJ14: =CF14-2*CI14*CA14 - 3*CH14*CA14^2 -> 0 | CK14: =CB14 -CH14*CA14^3 - CI14*CA14^2 - CJ14*CA14 -> 0.0253 | CN14: =$A14 -> 0 | CO14: =$B14 -> 0.0253 | CP14: =CN15 -> 0.75 | CQ14: =CO15 -> 0.0211 | CR14: =(CQ14-CO14)/(CP14-CN14) -> -0.0056 | CS14: 0 | CT14: =IF($F$5, (CR14*CR15>=0) * AVERAGE(CR14:CR15), AVERAGE(CR14:CR15)) -> 0 | CU14: =(CS14+CT14-2*(CQ14-CO14)/(CP14-CN14))/(CP14-CN14)^2 -> 0.019911111 | CV14: =((CQ14-CO14)/(CP14-CN14) - CS14 - CU14*(CP14^2 + CN14*CP14 - 2*CN14^2))/(CP14-CN14) -> -0.0224 | CW14: =CS14-2*CV14*CN14 - 3*CU14*CN14^2 -> 0 | CX14: =CO14 -CU14*CN14^3 - CV14*CN14^2 - CW14*CN14 -> 0.0253 | DA14: =$A14 -> 0 | DB14: =$B14 -> 0.0253 | DC14: =DA15 -> 0.75 | DD14: =DB15 -> 0.0211 | DE14: =(DD14-DB14)/(DC14-DA14) -> -0.0056 | DF14: 0 | DG14: =IF($F$5, (DE14*DE15>=0) * AVERAGE(DE14:DE15), AVERAGE(DE14:DE15)) -> 0 | DH14: =(DF14+DG14-2*(DD14-DB14)/(DC14-DA14))/(DC14-DA14)^2 -> 0.019911111 | DI14: =((DD14-DB14)/(DC14-DA14) - DF14 - DH14*(DC14^2 + DA14*DC14 - 2*DA14^2))/(DC14-DA14) -> -0.0224 | DJ14: =DF14-2*DI14*DA14 - 3*DH14*DA14^2 -> 0 | DK14: =DB14 -DH14*DA14^3 - DI14*DA14^2 - DJ14*DA14 -> 0.0253
A15: =C3-0.25 -> 0.75 | B15: =B14 + 2*(A15-A14)/0.25 / ((A15-A14)/0.25+1) * ((B3*C3 - B2*C2)/(C3-C2) - B14) -> 0.0211 | C15: =A16 -> 1.75 | D15: =B16 -> 0.0235 | E15: =(D15-B15)/(C15-A15) -> 0.0024 | F15: =G14 -> 0 | G15: =IF($F$5, (E15*E16>=0) * AVERAGE(E15:E16), AVERAGE(E15:E16)) -> 0.0024 | H15: =(F15+G15-2*(D15-B15)/(C15-A15))/(C15-A15)^2 -> -0.0024 | I15: =((D15-B15)/(C15-A15) - F15 - H15*(C15^2 + A15*C15 - 2*A15^2))/(C15-A15) -> 0.0102 | J15: =F15-2*I15*A15 - 3*H15*A15^2 -> -0.01125 | K15: =B15 -H15*A15^3 - I15*A15^2 - J15*A15 -> 0.0248125 | N15: =$A15 -> 0.75 | O15: =$B15 -> 0.0211 | P15: =N16 -> 1.75 | Q15: =O16 -> 0.0235 | R15: =(Q15-O15)/(P15-N15) -> 0.0024 | S15: =T14 -> 0 | T15: =IF($F$5, (R15*R16>=0) * AVERAGE(R15:R16), AVERAGE(R15:R16)) -> 0.0024 | U15: =(S15+T15-2*(Q15-O15)/(P15-N15))/(P15-N15)^2 -> -0.0024 | V15: =((Q15-O15)/(P15-N15) - S15 - U15*(P15^2 + N15*P15 - 2*N15^2))/(P15-N15) -> 0.0102 | W15: =S15-2*V15*N15 - 3*U15*N15^2 -> -0.01125 | X15: =O15 -U15*N15^3 - V15*N15^2 - W15*N15 -> 0.0248125 | AA15: =$A15 -> 0.75 | AB15: =$B15+Z13 -> 0.0212 | AC15: =AA16 -> 1.75 | AD15: =AB16 -> 0.0235 | AE15: =(AD15-AB15)/(AC15-AA15) -> 0.0023 | AF15: =AG14 -> 0 | AG15: =IF($F$5, (AE15*AE16>=0) * AVERAGE(AE15:AE16), AVERAGE(AE15:AE16)) -> 0.00235 | AH15: =(AF15+AG15-2*(AD15-AB15)/(AC15-AA15))/(AC15-AA15)^2 -> -0.00225 | AI15: =((AD15-AB15)/(AC15-AA15) - AF15 - AH15*(AC15^2 + AA15*AC15 - 2*AA15^2))/(AC15-AA15) -> 0.0096125 | AJ15: =AF15-2*AI15*AA15 - 3*AH15*AA15^2 -> -0.010621875 | AK15: =AB15 -AH15*AA15^3 - AI15*AA15^2 - AJ15*AA15 -> 0.024708594 | AN15: =$A15 -> 0.75 | AO15: =$B15 -> 0.0211 | AP15: =AN16 -> 1.75 | AQ15: =AO16 -> 0.0236 | AR15: =(AQ15-AO15)/(AP15-AN15) -> 0.0025 | AS15: =AT14 -> 0 | AT15: =IF($F$5, (AR15*AR16>=0) * AVERAGE(AR15:AR16), AVERAGE(AR15:AR16)) -> 0.0024 | AU15: =(AS15+AT15-2*(AQ15-AO15)/(AP15-AN15))/(AP15-AN15)^2 -> -0.0026 | AV15: =((AQ15-AO15)/(AP15-AN15) - AS15 - AU15*(AP15^2 + AN15*AP15 - 2*AN15^2))/(AP15-AN15) -> 0.01095 | AW15: =AS15-2*AV15*AN15 - 3*AU15*AN15^2 -> -0.0120375 | AX15: =AO15 -AU15*AN15^3 - AV15*AN15^2 - AW15*AN15 -> 0.025065625 | BA15: =$A15 -> 0.75 | BB15: =$B15 -> 0.0211 | BC15: =BA16 -> 1.75 | BD15: =BB16 -> 0.0235 | BE15: =(BD15-BB15)/(BC15-BA15) -> 0.0024 | BF15: =BG14 -> 0 | BG15: =IF($F$5, (BE15*BE16>=0) * AVERAGE(BE15:BE16), AVERAGE(BE15:BE16)) -> 0.00245 | BH15: =(BF15+BG15-2*(BD15-BB15)/(BC15-BA15))/(BC15-BA15)^2 -> -0.00235 | BI15: =((BD15-BB15)/(BC15-BA15) - BF15 - BH15*(BC15^2 + BA15*BC15 - 2*BA15^2))/(BC15-BA15) -> 0.0100375 | BJ15: =BF15-2*BI15*BA15 - 3*BH15*BA15^2 -> -0.011090625 | BK15: =BB15 -BH15*BA15^3 - BI15*BA15^2 - BJ15*BA15 -> 0.024763281 | BN15: =$A15 -> 0.75 | BO15: =$B15 -> 0.0211 | BP15: =BN16 -> 1.75 | BQ15: =BO16 -> 0.0235 | BR15: =(BQ15-BO15)/(BP15-BN15) -> 0.0024 | BS15: =BT14 -> 0 | BT15: =IF($F$5, (BR15*BR16>=0) * AVERAGE(BR15:BR16), AVERAGE(BR15:BR16)) -> 0.0024 | BU15: =(BS15+BT15-2*(BQ15-BO15)/(BP15-BN15))/(BP15-BN15)^2 -> -0.0024 | BV15: =((BQ15-BO15)/(BP15-BN15) - BS15 - BU15*(BP15^2 + BN15*BP15 - 2*BN15^2))/(BP15-BN15) -> 0.0102 | BW15: =BS15-2*BV15*BN15 - 3*BU15*BN15^2 -> -0.01125 | BX15: =BO15 -BU15*BN15^3 - BV15*BN15^2 - BW15*BN15 -> 0.0248125 | CA15: =$A15 -> 0.75 | CB15: =$B15 -> 0.0211 | CC15: =CA16 -> 1.75 | CD15: =CB16 -> 0.0235 | CE15: =(CD15-CB15)/(CC15-CA15) -> 0.0024 | CF15: =CG14 -> 0 | CG15: =IF($F$5, (CE15*CE16>=0) * AVERAGE(CE15:CE16), AVERAGE(CE15:CE16)) -> 0.0024 | CH15: =(CF15+CG15-2*(CD15-CB15)/(CC15-CA15))/(CC15-CA15)^2 -> -0.0024 | CI15: =((CD15-CB15)/(CC15-CA15) - CF15 - CH15*(CC15^2 + CA15*CC15 - 2*CA15^2))/(CC15-CA15) -> 0.0102 | CJ15: =CF15-2*CI15*CA15 - 3*CH15*CA15^2 -> -0.01125 | CK15: =CB15 -CH15*CA15^3 - CI15*CA15^2 - CJ15*CA15 -> 0.0248125 | CN15: =$A15 -> 0.75 | CO15: =$B15 -> 0.0211 | CP15: =CN16 -> 1.75 | CQ15: =CO16 -> 0.0235 | CR15: =(CQ15-CO15)/(CP15-CN15) -> 0.0024 | CS15: =CT14 -> 0 | CT15: =IF($F$5, (CR15*CR16>=0) * AVERAGE(CR15:CR16), AVERAGE(CR15:CR16)) -> 0.0024 | CU15: =(CS15+CT15-2*(CQ15-CO15)/(CP15-CN15))/(CP15-CN15)^2 -> -0.0024 | CV15: =((CQ15-CO15)/(CP15-CN15) - CS15 - CU15*(CP15^2 + CN15*CP15 - 2*CN15^2))/(CP15-CN15) -> 0.0102 | CW15: =CS15-2*CV15*CN15 - 3*CU15*CN15^2 -> -0.01125 | CX15: =CO15 -CU15*CN15^3 - CV15*CN15^2 - CW15*CN15 -> 0.0248125 | DA15: =$A15 -> 0.75 | DB15: =$B15 -> 0.0211 | DC15: =DA16 -> 1.75 | DD15: =DB16 -> 0.0235 | DE15: =(DD15-DB15)/(DC15-DA15) -> 0.0024 | DF15: =DG14 -> 0 | DG15: =IF($F$5, (DE15*DE16>=0) * AVERAGE(DE15:DE16), AVERAGE(DE15:DE16)) -> 0.0024 | DH15: =(DF15+DG15-2*(DD15-DB15)/(DC15-DA15))/(DC15-DA15)^2 -> -0.0024 | DI15: =((DD15-DB15)/(DC15-DA15) - DF15 - DH15*(DC15^2 + DA15*DC15 - 2*DA15^2))/(DC15-DA15) -> 0.0102 | DJ15: =DF15-2*DI15*DA15 - 3*DH15*DA15^2 -> -0.01125 | DK15: =DB15 -DH15*DA15^3 - DI15*DA15^2 - DJ15*DA15 -> 0.0248125
A16: =C4-0.25 -> 1.75 | B16: =B15 + 2*(A16-A15)/0.25 / ((A16-A15)/0.25+1) * ((B4*C4 - B3*C3)/(C4-C3) - B15) -> 0.0235 | C16: =A17 -> 2.75 | D16: =B17 -> 0.0259 | E16: =(D16-B16)/(C16-A16) -> 0.0024 | F16: =G15 -> 0.0024 | G16: =IF($F$5, (E16*E17>=0) * AVERAGE(E16:E17), AVERAGE(E16:E17)) -> 0.00128 | H16: =(F16+G16-2*(D16-B16)/(C16-A16))/(C16-A16)^2 -> -0.00112 | I16: =((D16-B16)/(C16-A16) - F16 - H16*(C16^2 + A16*C16 - 2*A16^2))/(C16-A16) -> 0.007 | J16: =F16-2*I16*A16 - 3*H16*A16^2 -> -0.01181 | K16: =B16 -H16*A16^3 - I16*A16^2 - J16*A16 -> 0.0287325 | N16: =$A16 -> 1.75 | O16: =$B16 -> 0.0235 | P16: =N17 -> 2.75 | Q16: =O17 -> 0.0259 | R16: =(Q16-O16)/(P16-N16) -> 0.0024 | S16: =T15 -> 0.0024 | T16: =IF($F$5, (R16*R17>=0) * AVERAGE(R16:R17), AVERAGE(R16:R17)) -> 0.00128 | U16: =(S16+T16-2*(Q16-O16)/(P16-N16))/(P16-N16)^2 -> -0.00112 | V16: =((Q16-O16)/(P16-N16) - S16 - U16*(P16^2 + N16*P16 - 2*N16^2))/(P16-N16) -> 0.007 | W16: =S16-2*V16*N16 - 3*U16*N16^2 -> -0.01181 | X16: =O16 -U16*N16^3 - V16*N16^2 - W16*N16 -> 0.0287325 | AA16: =$A16 -> 1.75 | AB16: =$B16 -> 0.0235 | AC16: =AA17 -> 2.75 | AD16: =AB17 -> 0.0259 | AE16: =(AD16-AB16)/(AC16-AA16) -> 0.0024 | AF16: =AG15 -> 0.00235 | AG16: =IF($F$5, (AE16*AE17>=0) * AVERAGE(AE16:AE17), AVERAGE(AE16:AE17)) -> 0.00128 | AH16: =(AF16+AG16-2*(AD16-AB16)/(AC16-AA16))/(AC16-AA16)^2 -> -0.00117 | AI16: =((AD16-AB16)/(AC16-AA16) - AF16 - AH16*(AC16^2 + AA16*AC16 - 2*AA16^2))/(AC16-AA16) -> 0.0073625 | AJ16: =AF16-2*AI16*AA16 - 3*AH16*AA16^2 -> -0.012669375 | AK16: =AB16 -AH16*AA16^3 - AI16*AA16^2 - AJ16*AA16 -> 0.029394219 | AN16: =$A16 -> 1.75 | AO16: =$B16+AM13 -> 0.0236 | AP16: =AN17 -> 2.75 | AQ16: =AO17 -> 0.0259 | AR16: =(AQ16-AO16)/(AP16-AN16) -> 0.0023 | AS16: =AT15 -> 0.0024 | AT16: =IF($F$5, (AR16*AR17>=0) * AVERAGE(AR16:AR17), AVERAGE(AR16:AR17)) -> 0.00123 | AU16: =(AS16+AT16-2*(AQ16-AO16)/(AP16-AN16))/(AP16-AN16)^2 -> -0.00097 | AV16: =((AQ16-AO16)/(AP16-AN16) - AS16 - AU16*(AP16^2 + AN16*AP16 - 2*AN16^2))/(AP16-AN16) -> 0.0059625 | AW16: =AS16-2*AV16*AN16 - 3*AU16*AN16^2 -> -0.009556875 | AX16: =AO16 -AU16*AN16^3 - AV16*AN16^2 - AW16*AN16 -> 0.027262969 | BA16: =$A16 -> 1.75 | BB16: =$B16 -> 0.0235 | BC16: =BA17 -> 2.75 | BD16: =BB17 -> 0.026 | BE16: =(BD16-BB16)/(BC16-BA16) -> 0.0025 | BF16: =BG15 -> 0.00245 | BG16: =IF($F$5, (BE16*BE17>=0) * AVERAGE(BE16:BE17), AVERAGE(BE16:BE17)) -> 0.00128 | BH16: =(BF16+BG16-2*(BD16-BB16)/(BC16-BA16))/(BC16-BA16)^2 -> -0.00127 | BI16: =((BD16-BB16)/(BC16-BA16) - BF16 - BH16*(BC16^2 + BA16*BC16 - 2*BA16^2))/(BC16-BA16) -> 0.0079875 | BJ16: =BF16-2*BI16*BA16 - 3*BH16*BA16^2 -> -0.013838125 | BK16: =BB16 -BH16*BA16^3 - BI16*BA16^2 - BJ16*BA16 -> 0.030061406 | BN16: =$A16 -> 1.75 | BO16: =$B16 -> 0.0235 | BP16: =BN17 -> 2.75 | BQ16: =BO17 -> 0.0259 | BR16: =(BQ16-BO16)/(BP16-BN16) -> 0.0024 | BS16: =BT15 -> 0.0024 | BT16: =IF($F$5, (BR16*BR17>=0) * AVERAGE(BR16:BR17), AVERAGE(BR16:BR17)) -> 0.00133 | BU16: =(BS16+BT16-2*(BQ16-BO16)/(BP16-BN16))/(BP16-BN16)^2 -> -0.00107 | BV16: =((BQ16-BO16)/(BP16-BN16) - BS16 - BU16*(BP16^2 + BN16*BP16 - 2*BN16^2))/(BP16-BN16) -> 0.0066875 | BW16: =BS16-2*BV16*BN16 - 3*BU16*BN16^2 -> -0.011175625 | BX16: =BO16 -BU16*BN16^3 - BV16*BN16^2 - BW16*BN16 -> 0.028311406 | CA16: =$A16 -> 1.75 | CB16: =$B16 -> 0.0235 | CC16: =CA17 -> 2.75 | CD16: =CB17 -> 0.0259 | CE16: =(CD16-CB16)/(CC16-CA16) -> 0.0024 | CF16: =CG15 -> 0.0024 | CG16: =IF($F$5, (CE16*CE17>=0) * AVERAGE(CE16:CE17), AVERAGE(CE16:CE17)) -> 0.00128 | CH16: =(CF16+CG16-2*(CD16-CB16)/(CC16-CA16))/(CC16-CA16)^2 -> -0.00112 | CI16: =((CD16-CB16)/(CC16-CA16) - CF16 - CH16*(CC16^2 + CA16*CC16 - 2*CA16^2))/(CC16-CA16) -> 0.007 | CJ16: =CF16-2*CI16*CA16 - 3*CH16*CA16^2 -> -0.01181 | CK16: =CB16 -CH16*CA16^3 - CI16*CA16^2 - CJ16*CA16 -> 0.0287325 | CN16: =$A16 -> 1.75 | CO16: =$B16 -> 0.0235 | CP16: =CN17 -> 2.75 | CQ16: =CO17 -> 0.0259 | CR16: =(CQ16-CO16)/(CP16-CN16) -> 0.0024 | CS16: =CT15 -> 0.0024 | CT16: =IF($F$5, (CR16*CR17>=0) * AVERAGE(CR16:CR17), AVERAGE(CR16:CR17)) -> 0.00128 | CU16: =(CS16+CT16-2*(CQ16-CO16)/(CP16-CN16))/(CP16-CN16)^2 -> -0.00112 | CV16: =((CQ16-CO16)/(CP16-CN16) - CS16 - CU16*(CP16^2 + CN16*CP16 - 2*CN16^2))/(CP16-CN16) -> 0.007 | CW16: =CS16-2*CV16*CN16 - 3*CU16*CN16^2 -> -0.01181 | CX16: =CO16 -CU16*CN16^3 - CV16*CN16^2 - CW16*CN16 -> 0.0287325 | DA16: =$A16 -> 1.75 | DB16: =$B16 -> 0.0235 | DC16: =DA17 -> 2.75 | DD16: =DB17 -> 0.0259 | DE16: =(DD16-DB16)/(DC16-DA16) -> 0.0024 | DF16: =DG15 -> 0.0024 | DG16: =IF($F$5, (DE16*DE17>=0) * AVERAGE(DE16:DE17), AVERAGE(DE16:DE17)) -> 0.00128 | DH16: =(DF16+DG16-2*(DD16-DB16)/(DC16-DA16))/(DC16-DA16)^2 -> -0.00112 | DI16: =((DD16-DB16)/(DC16-DA16) - DF16 - DH16*(DC16^2 + DA16*DC16 - 2*DA16^2))/(DC16-DA16) -> 0.007 | DJ16: =DF16-2*DI16*DA16 - 3*DH16*DA16^2 -> -0.01181 | DK16: =DB16 -DH16*DA16^3 - DI16*DA16^2 - DJ16*DA16 -> 0.0287325
A17: =C5-0.25 -> 2.75 | B17: =B16 + 2*(A17-A16)/0.25 / ((A17-A16)/0.25+1) * ((B5*C5 - B4*C4)/(C5-C4) - B16) -> 0.0259 | C17: =A18 -> 3.75 | D17: =B18 -> 0.02606 | E17: =(D17-B17)/(C17-A17) -> 0.00016 | F17: =G16 -> 0.00128 | G17: =IF($F$5, (E17*E18>=0) * AVERAGE(E17:E18), AVERAGE(E17:E18)) -> 0.000992 | H17: =(F17+G17-2*(D17-B17)/(C17-A17))/(C17-A17)^2 -> 0.001952 | I17: =((D17-B17)/(C17-A17) - F17 - H17*(C17^2 + A17*C17 - 2*A17^2))/(C17-A17) -> -0.019176 | J17: =F17-2*I17*A17 - 3*H17*A17^2 -> 0.062462 | K17: =B17 -H17*A17^3 - I17*A17^2 - J17*A17 -> -0.0414475 | N17: =$A17 -> 2.75 | O17: =$B17 -> 0.0259 | P17: =N18 -> 3.75 | Q17: =O18 -> 0.02606 | R17: =(Q17-O17)/(P17-N17) -> 0.00016 | S17: =T16 -> 0.00128 | T17: =IF($F$5, (R17*R18>=0) * AVERAGE(R17:R18), AVERAGE(R17:R18)) -> 0.000992 | U17: =(S17+T17-2*(Q17-O17)/(P17-N17))/(P17-N17)^2 -> 0.001952 | V17: =((Q17-O17)/(P17-N17) - S17 - U17*(P17^2 + N17*P17 - 2*N17^2))/(P17-N17) -> -0.019176 | W17: =S17-2*V17*N17 - 3*U17*N17^2 -> 0.062462 | X17: =O17 -U17*N17^3 - V17*N17^2 - W17*N17 -> -0.0414475 | AA17: =$A17 -> 2.75 | AB17: =$B17 -> 0.0259 | AC17: =AA18 -> 3.75 | AD17: =AB18 -> 0.02606 | AE17: =(AD17-AB17)/(AC17-AA17) -> 0.00016 | AF17: =AG16 -> 0.00128 | AG17: =IF($F$5, (AE17*AE18>=0) * AVERAGE(AE17:AE18), AVERAGE(AE17:AE18)) -> 0.000992 | AH17: =(AF17+AG17-2*(AD17-AB17)/(AC17-AA17))/(AC17-AA17)^2 -> 0.001952 | AI17: =((AD17-AB17)/(AC17-AA17) - AF17 - AH17*(AC17^2 + AA17*AC17 - 2*AA17^2))/(AC17-AA17) -> -0.019176 | AJ17: =AF17-2*AI17*AA17 - 3*AH17*AA17^2 -> 0.062462 | AK17: =AB17 -AH17*AA17^3 - AI17*AA17^2 - AJ17*AA17 -> -0.0414475 | AN17: =$A17 -> 2.75 | AO17: =$B17 -> 0.0259 | AP17: =AN18 -> 3.75 | AQ17: =AO18 -> 0.02606 | AR17: =(AQ17-AO17)/(AP17-AN17) -> 0.00016 | AS17: =AT16 -> 0.00123 | AT17: =IF($F$5, (AR17*AR18>=0) * AVERAGE(AR17:AR18), AVERAGE(AR17:AR18)) -> 0.000992 | AU17: =(AS17+AT17-2*(AQ17-AO17)/(AP17-AN17))/(AP17-AN17)^2 -> 0.001902 | AV17: =((AQ17-AO17)/(AP17-AN17) - AS17 - AU17*(AP17^2 + AN17*AP17 - 2*AN17^2))/(AP17-AN17) -> -0.0186635 | AW17: =AS17-2*AV17*AN17 - 3*AU17*AN17^2 -> 0.060727625 | AX17: =AO17 -AU17*AN17^3 - AV17*AN17^2 - AW17*AN17 -> -0.039513906 | BA17: =$A17 -> 2.75 | BB17: =$B17+AZ13 -> 0.026 | BC17: =BA18 -> 3.75 | BD17: =BB18 -> 0.02606 | BE17: =(BD17-BB17)/(BC17-BA17) -> 6e-05 | BF17: =BG16 -> 0.00128 | BG17: =IF($F$5, (BE17*BE18>=0) * AVERAGE(BE17:BE18), AVERAGE(BE17:BE18)) -> 0.000942 | BH17: =(BF17+BG17-2*(BD17-BB17)/(BC17-BA17))/(BC17-BA17)^2 -> 0.002102 | BI17: =((BD17-BB17)/(BC17-BA17) - BF17 - BH17*(BC17^2 + BA17*BC17 - 2*BA17^2))/(BC17-BA17) -> -0.0206635 | BJ17: =BF17-2*BI17*BA17 - 3*BH17*BA17^2 -> 0.067240125 | BK17: =BB17 -BH17*BA17^3 - BI17*BA17^2 - BJ17*BA17 -> -0.046357656 | BN17: =$A17 -> 2.75 | BO17: =$B17 -> 0.0259 | BP17: =BN18 -> 3.75 | BQ17: =BO18 -> 0.02616 | BR17: =(BQ17-BO17)/(BP17-BN17) -> 0.00026 | BS17: =BT16 -> 0.00133 | BT17: =IF($F$5, (BR17*BR18>=0) * AVERAGE(BR17:BR18), AVERAGE(BR17:BR18)) -> 0.000992 | BU17: =(BS17+BT17-2*(BQ17-BO17)/(BP17-BN17))/(BP17-BN17)^2 -> 0.001802 | BV17: =((BQ17-BO17)/(BP17-BN17) - BS17 - BU17*(BP17^2 + BN17*BP17 - 2*BN17^2))/(BP17-BN17) -> -0.0177385 | BW17: =BS17-2*BV17*BN17 - 3*BU17*BN17^2 -> 0.058008875 | BX17: =BO17 -BU17*BN17^3 - BV17*BN17^2 - BW17*BN17 -> -0.036952969 | CA17: =$A17 -> 2.75 | CB17: =$B17 -> 0.0259 | CC17: =CA18 -> 3.75 | CD17: =CB18 -> 0.02606 | CE17: =(CD17-CB17)/(CC17-CA17) -> 0.00016 | CF17: =CG16 -> 0.00128 | CG17: =IF($F$5, (CE17*CE18>=0) * AVERAGE(CE17:CE18), AVERAGE(CE17:CE18)) -> 0.001042 | CH17: =(CF17+CG17-2*(CD17-CB17)/(CC17-CA17))/(CC17-CA17)^2 -> 0.002002 | CI17: =((CD17-CB17)/(CC17-CA17) - CF17 - CH17*(CC17^2 + CA17*CC17 - 2*CA17^2))/(CC17-CA17) -> -0.0196385 | CJ17: =CF17-2*CI17*CA17 - 3*CH17*CA17^2 -> 0.063871375 | CK17: =CB17 -CH17*CA17^3 - CI17*CA17^2 - CJ17*CA17 -> -0.042865469 | CN17: =$A17 -> 2.75 | CO17: =$B17 -> 0.0259 | CP17: =CN18 -> 3.75 | CQ17: =CO18 -> 0.02606 | CR17: =(CQ17-CO17)/(CP17-CN17) -> 0.00016 | CS17: =CT16 -> 0.00128 | CT17: =IF($F$5, (CR17*CR18>=0) * AVERAGE(CR17:CR18), AVERAGE(CR17:CR18)) -> 0.000992 | CU17: =(CS17+CT17-2*(CQ17-CO17)/(CP17-CN17))/(CP17-CN17)^2 -> 0.001952 | CV17: =((CQ17-CO17)/(CP17-CN17) - CS17 - CU17*(CP17^2 + CN17*CP17 - 2*CN17^2))/(CP17-CN17) -> -0.019176 | CW17: =CS17-2*CV17*CN17 - 3*CU17*CN17^2 -> 0.062462 | CX17: =CO17 -CU17*CN17^3 - CV17*CN17^2 - CW17*CN17 -> -0.0414475 | DA17: =$A17 -> 2.75 | DB17: =$B17 -> 0.0259 | DC17: =DA18 -> 3.75 | DD17: =DB18 -> 0.02606 | DE17: =(DD17-DB17)/(DC17-DA17) -> 0.00016 | DF17: =DG16 -> 0.00128 | DG17: =IF($F$5, (DE17*DE18>=0) * AVERAGE(DE17:DE18), AVERAGE(DE17:DE18)) -> 0.000992 | DH17: =(DF17+DG17-2*(DD17-DB17)/(DC17-DA17))/(DC17-DA17)^2 -> 0.001952 | DI17: =((DD17-DB17)/(DC17-DA17) - DF17 - DH17*(DC17^2 + DA17*DC17 - 2*DA17^2))/(DC17-DA17) -> -0.019176 | DJ17: =DF17-2*DI17*DA17 - 3*DH17*DA17^2 -> 0.062462 | DK17: =DB17 -DH17*DA17^3 - DI17*DA17^2 - DJ17*DA17 -> -0.0414475
A18: =C6-0.25 -> 3.75 | B18: =B17 + 2*(A18-A17)/0.25 / ((A18-A17)/0.25+1) * ((B6*C6 - B5*C5)/(C6-C5) - B17) -> 0.02606 | C18: =A19 -> 4.75 | D18: =B19 -> 0.027884 | E18: =(D18-B18)/(C18-A18) -> 0.001824 | F18: =G17 -> 0.000992 | G18: =IF($F$5, (E18*E19>=0) * AVERAGE(E18:E19), AVERAGE(E18:E19)) -> 0.00094133333 | H18: =(F18+G18-2*(D18-B18)/(C18-A18))/(C18-A18)^2 -> -0.0017146667 | I18: =((D18-B18)/(C18-A18) - F18 - H18*(C18^2 + A18*C18 - 2*A18^2))/(C18-A18) -> 0.021836667 | J18: =F18-2*I18*A18 - 3*H18*A18^2 -> -0.0904455 | K18: =B18 -H18*A18^3 - I18*A18^2 - J18*A18 -> 0.14857438 | N18: =$A18 -> 3.75 | O18: =$B18 -> 0.02606 | P18: =N19 -> 4.75 | Q18: =O19 -> 0.027884 | R18: =(Q18-O18)/(P18-N18) -> 0.001824 | S18: =T17 -> 0.000992 | T18: =IF($F$5, (R18*R19>=0) * AVERAGE(R18:R19), AVERAGE(R18:R19)) -> 0.00094133333 | U18: =(S18+T18-2*(Q18-O18)/(P18-N18))/(P18-N18)^2 -> -0.0017146667 | V18: =((Q18-O18)/(P18-N18) - S18 - U18*(P18^2 + N18*P18 - 2*N18^2))/(P18-N18) -> 0.021836667 | W18: =S18-2*V18*N18 - 3*U18*N18^2 -> -0.0904455 | X18: =O18 -U18*N18^3 - V18*N18^2 - W18*N18 -> 0.14857438 | AA18: =$A18 -> 3.75 | AB18: =$B18 -> 0.02606 | AC18: =AA19 -> 4.75 | AD18: =AB19 -> 0.027884 | AE18: =(AD18-AB18)/(AC18-AA18) -> 0.001824 | AF18: =AG17 -> 0.000992 | AG18: =IF($F$5, (AE18*AE19>=0) * AVERAGE(AE18:AE19), AVERAGE(AE18:AE19)) -> 0.00094133333 | AH18: =(AF18+AG18-2*(AD18-AB18)/(AC18-AA18))/(AC18-AA18)^2 -> -0.0017146667 | AI18: =((AD18-AB18)/(AC18-AA18) - AF18 - AH18*(AC18^2 + AA18*AC18 - 2*AA18^2))/(AC18-AA18) -> 0.021836667 | AJ18: =AF18-2*AI18*AA18 - 3*AH18*AA18^2 -> -0.0904455 | AK18: =AB18 -AH18*AA18^3 - AI18*AA18^2 - AJ18*AA18 -> 0.14857438 | AN18: =$A18 -> 3.75 | AO18: =$B18 -> 0.02606 | AP18: =AN19 -> 4.75 | AQ18: =AO19 -> 0.027884 | AR18: =(AQ18-AO18)/(AP18-AN18) -> 0.001824 | AS18: =AT17 -> 0.000992 | AT18: =IF($F$5, (AR18*AR19>=0) * AVERAGE(AR18:AR19), AVERAGE(AR18:AR19)) -> 0.00094133333 | AU18: =(AS18+AT18-2*(AQ18-AO18)/(AP18-AN18))/(AP18-AN18)^2 -> -0.0017146667 | AV18: =((AQ18-AO18)/(AP18-AN18) - AS18 - AU18*(AP18^2 + AN18*AP18 - 2*AN18^2))/(AP18-AN18) -> 0.021836667 | AW18: =AS18-2*AV18*AN18 - 3*AU18*AN18^2 -> -0.0904455 | AX18: =AO18 -AU18*AN18^3 - AV18*AN18^2 - AW18*AN18 -> 0.14857438 | BA18: =$A18 -> 3.75 | BB18: =$B18 -> 0.02606 | BC18: =BA19 -> 4.75 | BD18: =BB19 -> 0.027884 | BE18: =(BD18-BB18)/(BC18-BA18) -> 0.001824 | BF18: =BG17 -> 0.000942 | BG18: =IF($F$5, (BE18*BE19>=0) * AVERAGE(BE18:BE19), AVERAGE(BE18:BE19)) -> 0.00094133333 | BH18: =(BF18+BG18-2*(BD18-BB18)/(BC18-BA18))/(BC18-BA18)^2 -> -0.0017646667 | BI18: =((BD18-BB18)/(BC18-BA18) - BF18 - BH18*(BC18^2 + BA18*BC18 - 2*BA18^2))/(BC18-BA18) -> 0.022499167 | BJ18: =BF18-2*BI18*BA18 - 3*BH18*BA18^2 -> -0.093354875 | BK18: =BB18 -BH18*BA18^3 - BI18*BA18^2 - BJ18*BA18 -> 0.15280484 | BN18: =$A18 -> 3.75 | BO18: =$B18+BM13 -> 0.02616 | BP18: =BN19 -> 4.75 | BQ18: =BO19 -> 0.027884 | BR18: =(BQ18-BO18)/(BP18-BN18) -> 0.001724 | BS18: =BT17 -> 0.000992 | BT18: =IF($F$5, (BR18*BR19>=0) * AVERAGE(BR18:BR19), AVERAGE(BR18:BR19)) -> 0.00089133333 | BU18: =(BS18+BT18-2*(BQ18-BO18)/(BP18-BN18))/(BP18-BN18)^2 -> -0.0015646667 | BV18: =((BQ18-BO18)/(BP18-BN18) - BS18 - BU18*(BP18^2 + BN18*BP18 - 2*BN18^2))/(BP18-BN18) -> 0.019899167 | BW18: =BS18-2*BV18*BN18 - 3*BU18*BN18^2 -> -0.082242375 | BX18: =BO18 -BU18*BN18^3 - BV18*BN18^2 - BW18*BN18 -> 0.13724859 | CA18: =$A18 -> 3.75 | CB18: =$B18 -> 0.02606 | CC18: =CA19 -> 4.75 | CD18: =CB19 -> 0.027984 | CE18: =(CD18-CB18)/(CC18-CA18) -> 0.001924 | CF18: =CG17 -> 0.001042 | CG18: =IF($F$5, (CE18*CE19>=0) * AVERAGE(CE18:CE19), AVERAGE(CE18:CE19)) -> 0.00096633333 | CH18: =(CF18+CG18-2*(CD18-CB18)/(CC18-CA18))/(CC18-CA18)^2 -> -0.0018396667 | CI18: =((CD18-CB18)/(CC18-CA18) - CF18 - CH18*(CC18^2 + CA18*CC18 - 2*CA18^2))/(CC18-CA18) -> 0.023417917 | CJ18: =CF18-2*CI18*CA18 - 3*CH18*CA18^2 -> -0.096981438 | CK18: =CB18 -CH18*CA18^3 - CI18*CA18^2 - CJ18*CA18 -> 0.15743961 | CN18: =$A18 -> 3.75 | CO18: =$B18 -> 0.02606 | CP18: =CN19 -> 4.75 | CQ18: =CO19 -> 0.027884 | CR18: =(CQ18-CO18)/(CP18-CN18) -> 0.001824 | CS18: =CT17 -> 0.000992 | CT18: =IF($F$5, (CR18*CR19>=0) * AVERAGE(CR18:CR19), AVERAGE(CR18:CR19)) -> 0.00096633333 | CU18: =(CS18+CT18-2*(CQ18-CO18)/(CP18-CN18))/(CP18-CN18)^2 -> -0.0016896667 | CV18: =((CQ18-CO18)/(CP18-CN18) - CS18 - CU18*(CP18^2 + CN18*CP18 - 2*CN18^2))/(CP18-CN18) -> 0.021530417 | CW18: =CS18-2*CV18*CN18 - 3*CU18*CN18^2 -> -0.089203313 | CX18: =CO18 -CU18*CN18^3 - CV18*CN18^2 - CW18*CN18 -> 0.14690445 | DA18: =$A18 -> 3.75 | DB18: =$B18 -> 0.02606 | DC18: =DA19 -> 4.75 | DD18: =DB19 -> 0.027884 | DE18: =(DD18-DB18)/(DC18-DA18) -> 0.001824 | DF18: =DG17 -> 0.000992 | DG18: =IF($F$5, (DE18*DE19>=0) * AVERAGE(DE18:DE19), AVERAGE(DE18:DE19)) -> 0.00094133333 | DH18: =(DF18+DG18-2*(DD18-DB18)/(DC18-DA18))/(DC18-DA18)^2 -> -0.0017146667 | DI18: =((DD18-DB18)/(DC18-DA18) - DF18 - DH18*(DC18^2 + DA18*DC18 - 2*DA18^2))/(DC18-DA18) -> 0.021836667 | DJ18: =DF18-2*DI18*DA18 - 3*DH18*DA18^2 -> -0.0904455 | DK18: =DB18 -DH18*DA18^3 - DI18*DA18^2 - DJ18*DA18 -> 0.14857438
A19: =C7-0.25 -> 4.75 | B19: =B18 + 2*(A19-A18)/0.25 / ((A19-A18)/0.25+1) * ((B7*C7 - B6*C6)/(C7-C6) - B18) -> 0.027884 | C19: =A20 -> 6.75 | D19: =B20 -> 0.028001333 | E19: =(D19-B19)/(C19-A19) -> 5.8666667e-05 | F19: =G18 -> 0.00094133333 | G19: =IF($F$5, (E19*E20>=0) * AVERAGE(E19:E20), AVERAGE(E19:E20)) -> 0.000552 | H19: =(F19+G19-2*(D19-B19)/(C19-A19))/(C19-A19)^2 -> 0.000344 | I19: =((D19-B19)/(C19-A19) - F19 - H19*(C19^2 + A19*C19 - 2*A19^2))/(C19-A19) -> -0.0060313333 | J19: =F19-2*I19*A19 - 3*H19*A19^2 -> 0.0349545 | K19: =B19 -H19*A19^3 - I19*A19^2 - J19*A19 -> -0.038935042 | N19: =$A19 -> 4.75 | O19: =$B19 -> 0.027884 | P19: =N20 -> 6.75 | Q19: =O20 -> 0.028001333 | R19: =(Q19-O19)/(P19-N19) -> 5.8666667e-05 | S19: =T18 -> 0.00094133333 | T19: =IF($F$5, (R19*R20>=0) * AVERAGE(R19:R20), AVERAGE(R19:R20)) -> 0.000552 | U19: =(S19+T19-2*(Q19-O19)/(P19-N19))/(P19-N19)^2 -> 0.000344 | V19: =((Q19-O19)/(P19-N19) - S19 - U19*(P19^2 + N19*P19 - 2*N19^2))/(P19-N19) -> -0.0060313333 | W19: =S19-2*V19*N19 - 3*U19*N19^2 -> 0.0349545 | X19: =O19 -U19*N19^3 - V19*N19^2 - W19*N19 -> -0.038935042 | AA19: =$A19 -> 4.75 | AB19: =$B19 -> 0.027884 | AC19: =AA20 -> 6.75 | AD19: =AB20 -> 0.028001333 | AE19: =(AD19-AB19)/(AC19-AA19) -> 5.8666667e-05 | AF19: =AG18 -> 0.00094133333 | AG19: =IF($F$5, (AE19*AE20>=0) * AVERAGE(AE19:AE20), AVERAGE(AE19:AE20)) -> 0.000552 | AH19: =(AF19+AG19-2*(AD19-AB19)/(AC19-AA19))/(AC19-AA19)^2 -> 0.000344 | AI19: =((AD19-AB19)/(AC19-AA19) - AF19 - AH19*(AC19^2 + AA19*AC19 - 2*AA19^2))/(AC19-AA19) -> -0.0060313333 | AJ19: =AF19-2*AI19*AA19 - 3*AH19*AA19^2 -> 0.0349545 | AK19: =AB19 -AH19*AA19^3 - AI19*AA19^2 - AJ19*AA19 -> -0.038935042 | AN19: =$A19 -> 4.75 | AO19: =$B19 -> 0.027884 | AP19: =AN20 -> 6.75 | AQ19: =AO20 -> 0.028001333 | AR19: =(AQ19-AO19)/(AP19-AN19) -> 5.8666667e-05 | AS19: =AT18 -> 0.00094133333 | AT19: =IF($F$5, (AR19*AR20>=0) * AVERAGE(AR19:AR20), AVERAGE(AR19:AR20)) -> 0.000552 | AU19: =(AS19+AT19-2*(AQ19-AO19)/(AP19-AN19))/(AP19-AN19)^2 -> 0.000344 | AV19: =((AQ19-AO19)/(AP19-AN19) - AS19 - AU19*(AP19^2 + AN19*AP19 - 2*AN19^2))/(AP19-AN19) -> -0.0060313333 | AW19: =AS19-2*AV19*AN19 - 3*AU19*AN19^2 -> 0.0349545 | AX19: =AO19 -AU19*AN19^3 - AV19*AN19^2 - AW19*AN19 -> -0.038935042 | BA19: =$A19 -> 4.75 | BB19: =$B19 -> 0.027884 | BC19: =BA20 -> 6.75 | BD19: =BB20 -> 0.028001333 | BE19: =(BD19-BB19)/(BC19-BA19) -> 5.8666667e-05 | BF19: =BG18 -> 0.00094133333 | BG19: =IF($F$5, (BE19*BE20>=0) * AVERAGE(BE19:BE20), AVERAGE(BE19:BE20)) -> 0.000552 | BH19: =(BF19+BG19-2*(BD19-BB19)/(BC19-BA19))/(BC19-BA19)^2 -> 0.000344 | BI19: =((BD19-BB19)/(BC19-BA19) - BF19 - BH19*(BC19^2 + BA19*BC19 - 2*BA19^2))/(BC19-BA19) -> -0.0060313333 | BJ19: =BF19-2*BI19*BA19 - 3*BH19*BA19^2 -> 0.0349545 | BK19: =BB19 -BH19*BA19^3 - BI19*BA19^2 - BJ19*BA19 -> -0.038935042 | BN19: =$A19 -> 4.75 | BO19: =$B19 -> 0.027884 | BP19: =BN20 -> 6.75 | BQ19: =BO20 -> 0.028001333 | BR19: =(BQ19-BO19)/(BP19-BN19) -> 5.8666667e-05 | BS19: =BT18 -> 0.00089133333 | BT19: =IF($F$5, (BR19*BR20>=0) * AVERAGE(BR19:BR20), AVERAGE(BR19:BR20)) -> 0.000552 | BU19: =(BS19+BT19-2*(BQ19-BO19)/(BP19-BN19))/(BP19-BN19)^2 -> 0.0003315 | BV19: =((BQ19-BO19)/(BP19-BN19) - BS19 - BU19*(BP19^2 + BN19*BP19 - 2*BN19^2))/(BP19-BN19) -> -0.0058032083 | BW19: =BS19-2*BV19*BN19 - 3*BU19*BN19^2 -> 0.033583406 | BX19: =BO19 -BU19*BN19^3 - BV19*BN19^2 - BW19*BN19 -> -0.036229768 | CA19: =$A19 -> 4.75 | CB19: =$B19+BZ13 -> 0.027984 | CC19: =CA20 -> 6.75 | CD19: =CB20 -> 0.028001333 | CE19: =(CD19-CB19)/(CC19-CA19) -> 8.6666667e-06 | CF19: =CG18 -> 0.00096633333 | CG19: =IF($F$5, (CE19*CE20>=0) * AVERAGE(CE19:CE20), AVERAGE(CE19:CE20)) -> 0.000527 | CH19: =(CF19+CG19-2*(CD19-CB19)/(CC19-CA19))/(CC19-CA19)^2 -> 0.000369 | CI19: =((CD19-CB19)/(CC19-CA19) - CF19 - CH19*(CC19^2 + CA19*CC19 - 2*CA19^2))/(CC19-CA19) -> -0.0064750833 | CJ19: =CF19-2*CI19*CA19 - 3*CH19*CA19^2 -> 0.037502938 | CK19: =CB19 -CH19*CA19^3 - CI19*CA19^2 - CJ19*CA19 -> -0.043607307 | CN19: =$A19 -> 4.75 | CO19: =$B19 -> 0.027884 | CP19: =CN20 -> 6.75 | CQ19: =CO20 -> 0.028101333 | CR19: =(CQ19-CO19)/(CP19-CN19) -> 0.00010866667 | CS19: =CT18 -> 0.00096633333 | CT19: =IF($F$5, (CR19*CR20>=0) * AVERAGE(CR19:CR20), AVERAGE(CR19:CR20)) -> 0.00056033333 | CU19: =(CS19+CT19-2*(CQ19-CO19)/(CP19-CN19))/(CP19-CN19)^2 -> 0.00032733333 | CV19: =((CQ19-CO19)/(CP19-CN19) - CS19 - CU19*(CP19^2 + CN19*CP19 - 2*CN19^2))/(CP19-CN19) -> -0.005748 | CW19: =CS19-2*CV19*CN19 - 3*CU19*CN19^2 -> 0.033415958 | CX19: =CO19 -CU19*CN19^3 - CV19*CN19^2 - CW19*CN19 -> -0.036233479 | DA19: =$A19 -> 4.75 | DB19: =$B19 -> 0.027884 | DC19: =DA20 -> 6.75 | DD19: =DB20 -> 0.028001333 | DE19: =(DD19-DB19)/(DC19-DA19) -> 5.8666667e-05 | DF19: =DG18 -> 0.00094133333 | DG19: =IF($F$5, (DE19*DE20>=0) * AVERAGE(DE19:DE20), AVERAGE(DE19:DE20)) -> 0.00056866667 | DH19: =(DF19+DG19-2*(DD19-DB19)/(DC19-DA19))/(DC19-DA19)^2 -> 0.00034816667 | DI19: =((DD19-DB19)/(DC19-DA19) - DF19 - DH19*(DC19^2 + DA19*DC19 - 2*DA19^2))/(DC19-DA19) -> -0.0060990417 | DJ19: =DF19-2*DI19*DA19 - 3*DH19*DA19^2 -> 0.035315698 | DK19: =DB19 -DH19*DA19^3 - DI19*DA19^2 - DJ19*DA19 -> -0.039569612
A20: =C8-0.25 -> 6.75 | B20: =B19 + 2*(A20-A19)/0.25 / ((A20-A19)/0.25+1) * ((B8*C8 - B7*C7)/(C8-C7) - B19) -> 0.028001333 | C20: =A21 -> 9.75 | D20: =B21 -> 0.031137333 | E20: =(D20-B20)/(C20-A20) -> 0.0010453333 | F20: =G19 -> 0.000552 | G20: =IF($F$5, (E20*E21>=0) * AVERAGE(E20:E21), AVERAGE(E20:E21)) -> 0.00052266667 | H20: =(F20+G20-2*(D20-B20)/(C20-A20))/(C20-A20)^2 -> -0.00011288889 | I20: =((D20-B20)/(C20-A20) - F20 - H20*(C20^2 + A20*C20 - 2*A20^2))/(C20-A20) -> 0.0027891111 | J20: =F20-2*I20*A20 - 3*H20*A20^2 -> -0.0216705 | K20: =B20 -H20*A20^3 - I20*A20^2 - J20*A20 -> 0.081916958 | N20: =$A20 -> 6.75 | O20: =$B20 -> 0.028001333 | P20: =N21 -> 9.75 | Q20: =O21 -> 0.031137333 | R20: =(Q20-O20)/(P20-N20) -> 0.0010453333 | S20: =T19 -> 0.000552 | T20: =IF($F$5, (R20*R21>=0) * AVERAGE(R20:R21), AVERAGE(R20:R21)) -> 0.00052266667 | U20: =(S20+T20-2*(Q20-O20)/(P20-N20))/(P20-N20)^2 -> -0.00011288889 | V20: =((Q20-O20)/(P20-N20) - S20 - U20*(P20^2 + N20*P20 - 2*N20^2))/(P20-N20) -> 0.0027891111 | W20: =S20-2*V20*N20 - 3*U20*N20^2 -> -0.0216705 | X20: =O20 -U20*N20^3 - V20*N20^2 - W20*N20 -> 0.081916958 | AA20: =$A20 -> 6.75 | AB20: =$B20 -> 0.028001333 | AC20: =AA21 -> 9.75 | AD20: =AB21 -> 0.031137333 | AE20: =(AD20-AB20)/(AC20-AA20) -> 0.0010453333 | AF20: =AG19 -> 0.000552 | AG20: =IF($F$5, (AE20*AE21>=0) * AVERAGE(AE20:AE21), AVERAGE(AE20:AE21)) -> 0.00052266667 | AH20: =(AF20+AG20-2*(AD20-AB20)/(AC20-AA20))/(AC20-AA20)^2 -> -0.00011288889 | AI20: =((AD20-AB20)/(AC20-AA20) - AF20 - AH20*(AC20^2 + AA20*AC20 - 2*AA20^2))/(AC20-AA20) -> 0.0027891111 | AJ20: =AF20-2*AI20*AA20 - 3*AH20*AA20^2 -> -0.0216705 | AK20: =AB20 -AH20*AA20^3 - AI20*AA20^2 - AJ20*AA20 -> 0.081916958 | AN20: =$A20 -> 6.75 | AO20: =$B20 -> 0.028001333 | AP20: =AN21 -> 9.75 | AQ20: =AO21 -> 0.031137333 | AR20: =(AQ20-AO20)/(AP20-AN20) -> 0.0010453333 | AS20: =AT19 -> 0.000552 | AT20: =IF($F$5, (AR20*AR21>=0) * AVERAGE(AR20:AR21), AVERAGE(AR20:AR21)) -> 0.00052266667 | AU20: =(AS20+AT20-2*(AQ20-AO20)/(AP20-AN20))/(AP20-AN20)^2 -> -0.00011288889 | AV20: =((AQ20-AO20)/(AP20-AN20) - AS20 - AU20*(AP20^2 + AN20*AP20 - 2*AN20^2))/(AP20-AN20) -> 0.0027891111 | AW20: =AS20-2*AV20*AN20 - 3*AU20*AN20^2 -> -0.0216705 | AX20: =AO20 -AU20*AN20^3 - AV20*AN20^2 - AW20*AN20 -> 0.081916958 | BA20: =$A20 -> 6.75 | BB20: =$B20 -> 0.028001333 | BC20: =BA21 -> 9.75 | BD20: =BB21 -> 0.031137333 | BE20: =(BD20-BB20)/(BC20-BA20) -> 0.0010453333 | BF20: =BG19 -> 0.000552 | BG20: =IF($F$5, (BE20*BE21>=0) * AVERAGE(BE20:BE21), AVERAGE(BE20:BE21)) -> 0.00052266667 | BH20: =(BF20+BG20-2*(BD20-BB20)/(BC20-BA20))/(BC20-BA20)^2 -> -0.00011288889 | BI20: =((BD20-BB20)/(BC20-BA20) - BF20 - BH20*(BC20^2 + BA20*BC20 - 2*BA20^2))/(BC20-BA20) -> 0.0027891111 | BJ20: =BF20-2*BI20*BA20 - 3*BH20*BA20^2 -> -0.0216705 | BK20: =BB20 -BH20*BA20^3 - BI20*BA20^2 - BJ20*BA20 -> 0.081916958 | BN20: =$A20 -> 6.75 | BO20: =$B20 -> 0.028001333 | BP20: =BN21 -> 9.75 | BQ20: =BO21 -> 0.031137333 | BR20: =(BQ20-BO20)/(BP20-BN20) -> 0.0010453333 | BS20: =BT19 -> 0.000552 | BT20: =IF($F$5, (BR20*BR21>=0) * AVERAGE(BR20:BR21), AVERAGE(BR20:BR21)) -> 0.00052266667 | BU20: =(BS20+BT20-2*(BQ20-BO20)/(BP20-BN20))/(BP20-BN20)^2 -> -0.00011288889 | BV20: =((BQ20-BO20)/(BP20-BN20) - BS20 - BU20*(BP20^2 + BN20*BP20 - 2*BN20^2))/(BP20-BN20) -> 0.0027891111 | BW20: =BS20-2*BV20*BN20 - 3*BU20*BN20^2 -> -0.0216705 | BX20: =BO20 -BU20*BN20^3 - BV20*BN20^2 - BW20*BN20 -> 0.081916958 | CA20: =$A20 -> 6.75 | CB20: =$B20 -> 0.028001333 | CC20: =CA21 -> 9.75 | CD20: =CB21 -> 0.031137333 | CE20: =(CD20-CB20)/(CC20-CA20) -> 0.0010453333 | CF20: =CG19 -> 0.000527 | CG20: =IF($F$5, (CE20*CE21>=0) * AVERAGE(CE20:CE21), AVERAGE(CE20:CE21)) -> 0.00052266667 | CH20: =(CF20+CG20-2*(CD20-CB20)/(CC20-CA20))/(CC20-CA20)^2 -> -0.00011566667 | CI20: =((CD20-CB20)/(CC20-CA20) - CF20 - CH20*(CC20^2 + CA20*CC20 - 2*CA20^2))/(CC20-CA20) -> 0.0028620278 | CJ20: =CF20-2*CI20*CA20 - 3*CH20*CA20^2 -> -0.022300188 | CK20: =CB20 -CH20*CA20^3 - CI20*CA20^2 - CJ20*CA20 -> 0.08369938 | CN20: =$A20 -> 6.75 | CO20: =$B20+CM13 -> 0.028101333 | CP20: =CN21 -> 9.75 | CQ20: =CO21 -> 0.031137333 | CR20: =(CQ20-CO20)/(CP20-CN20) -> 0.001012 | CS20: =CT19 -> 0.00056033333 | CT20: =IF($F$5, (CR20*CR21>=0) * AVERAGE(CR20:CR21), AVERAGE(CR20:CR21)) -> 0.000506 | CU20: =(CS20+CT20-2*(CQ20-CO20)/(CP20-CN20))/(CP20-CN20)^2 -> -0.00010640741 | CV20: =((CQ20-CO20)/(CP20-CN20) - CS20 - CU20*(CP20^2 + CN20*CP20 - 2*CN20^2))/(CP20-CN20) -> 0.0026245278 | CW20: =CS20-2*CV20*CN20 - 3*CU20*CN20^2 -> -0.020326229 | CX20: =CO20 -CU20*CN20^3 - CV20*CN20^2 - CW20*CN20 -> 0.078448599 | DA20: =$A20 -> 6.75 | DB20: =$B20 -> 0.028001333 | DC20: =DA21 -> 9.75 | DD20: =DB21 -> 0.031237333 | DE20: =(DD20-DB20)/(DC20-DA20) -> 0.0010786667 | DF20: =DG19 -> 0.00056866667 | DG20: =IF($F$5, (DE20*DE21>=0) * AVERAGE(DE20:DE21), AVERAGE(DE20:DE21)) -> 0.00053933333 | DH20: =(DF20+DG20-2*(DD20-DB20)/(DC20-DA20))/(DC20-DA20)^2 -> -0.00011659259 | DI20: =((DD20-DB20)/(DC20-DA20) - DF20 - DH20*(DC20^2 + DA20*DC20 - 2*DA20^2))/(DC20-DA20) -> 0.0028807778 | DJ20: =DF20-2*DI20*DA20 - 3*DH20*DA20^2 -> -0.022385083 | DK20: =DB20 -DH20*DA20^3 - DI20*DA20^2 - DJ20*DA20 -> 0.083702896
A21: =C9-0.25 -> 9.75 | B21: =B20 + 2*(A21-A20)/0.25 / ((A21-A20)/0.25+1) * ((B9*C9 - B8*C8)/(C9-C8) - B20) -> 0.031137333 | C21: 100 | D21: =B21 -> 0.031137333 | E21: =(D21-B21)/(C21-A21) -> 0 | F21: =G20 -> 0.00052266667 | G21: 0 | H21: =(F21+G21-2*(D21-B21)/(C21-A21))/(C21-A21)^2 -> 6.4169755e-08 | I21: =((D21-B21)/(C21-A21) - F21 - H21*(C21^2 + A21*C21 - 2*A21^2))/(C21-A21) -> -1.3459606e-05 | J21: =F21-2*I21*A21 - 3*H21*A21^2 -> 0.00076682857 | K21: =B21 -H21*A21^3 - I21*A21^2 - J21*A21 -> 0.024880782 | N21: =$A21 -> 9.75 | O21: =$B21 -> 0.031137333 | P21: 100 | Q21: =O21 -> 0.031137333 | R21: =(Q21-O21)/(P21-N21) -> 0 | S21: =T20 -> 0.00052266667 | T21: 0 | U21: =(S21+T21-2*(Q21-O21)/(P21-N21))/(P21-N21)^2 -> 6.4169755e-08 | V21: =((Q21-O21)/(P21-N21) - S21 - U21*(P21^2 + N21*P21 - 2*N21^2))/(P21-N21) -> -1.3459606e-05 | W21: =S21-2*V21*N21 - 3*U21*N21^2 -> 0.00076682857 | X21: =O21 -U21*N21^3 - V21*N21^2 - W21*N21 -> 0.024880782 | AA21: =$A21 -> 9.75 | AB21: =$B21 -> 0.031137333 | AC21: 100 | AD21: =AB21 -> 0.031137333 | AE21: =(AD21-AB21)/(AC21-AA21) -> 0 | AF21: =AG20 -> 0.00052266667 | AG21: 0 | AH21: =(AF21+AG21-2*(AD21-AB21)/(AC21-AA21))/(AC21-AA21)^2 -> 6.4169755e-08 | AI21: =((AD21-AB21)/(AC21-AA21) - AF21 - AH21*(AC21^2 + AA21*AC21 - 2*AA21^2))/(AC21-AA21) -> -1.3459606e-05 | AJ21: =AF21-2*AI21*AA21 - 3*AH21*AA21^2 -> 0.00076682857 | AK21: =AB21 -AH21*AA21^3 - AI21*AA21^2 - AJ21*AA21 -> 0.024880782 | AN21: =$A21 -> 9.75 | AO21: =$B21 -> 0.031137333 | AP21: 100 | AQ21: =AO21 -> 0.031137333 | AR21: =(AQ21-AO21)/(AP21-AN21) -> 0 | AS21: =AT20 -> 0.00052266667 | AT21: 0 | AU21: =(AS21+AT21-2*(AQ21-AO21)/(AP21-AN21))/(AP21-AN21)^2 -> 6.4169755e-08 | AV21: =((AQ21-AO21)/(AP21-AN21) - AS21 - AU21*(AP21^2 + AN21*AP21 - 2*AN21^2))/(AP21-AN21) -> -1.3459606e-05 | AW21: =AS21-2*AV21*AN21 - 3*AU21*AN21^2 -> 0.00076682857 | AX21: =AO21 -AU21*AN21^3 - AV21*AN21^2 - AW21*AN21 -> 0.024880782 | BA21: =$A21 -> 9.75 | BB21: =$B21 -> 0.031137333 | BC21: 100 | BD21: =BB21 -> 0.031137333 | BE21: =(BD21-BB21)/(BC21-BA21) -> 0 | BF21: =BG20 -> 0.00052266667 | BG21: 0 | BH21: =(BF21+BG21-2*(BD21-BB21)/(BC21-BA21))/(BC21-BA21)^2 -> 6.4169755e-08 | BI21: =((BD21-BB21)/(BC21-BA21) - BF21 - BH21*(BC21^2 + BA21*BC21 - 2*BA21^2))/(BC21-BA21) -> -1.3459606e-05 | BJ21: =BF21-2*BI21*BA21 - 3*BH21*BA21^2 -> 0.00076682857 | BK21: =BB21 -BH21*BA21^3 - BI21*BA21^2 - BJ21*BA21 -> 0.024880782 | BN21: =$A21 -> 9.75 | BO21: =$B21 -> 0.031137333 | BP21: 100 | BQ21: =BO21 -> 0.031137333 | BR21: =(BQ21-BO21)/(BP21-BN21) -> 0 | BS21: =BT20 -> 0.00052266667 | BT21: 0 | BU21: =(BS21+BT21-2*(BQ21-BO21)/(BP21-BN21))/(BP21-BN21)^2 -> 6.4169755e-08 | BV21: =((BQ21-BO21)/(BP21-BN21) - BS21 - BU21*(BP21^2 + BN21*BP21 - 2*BN21^2))/(BP21-BN21) -> -1.3459606e-05 | BW21: =BS21-2*BV21*BN21 - 3*BU21*BN21^2 -> 0.00076682857 | BX21: =BO21 -BU21*BN21^3 - BV21*BN21^2 - BW21*BN21 -> 0.024880782 | CA21: =$A21 -> 9.75 | CB21: =$B21 -> 0.031137333 | CC21: 100 | CD21: =CB21 -> 0.031137333 | CE21: =(CD21-CB21)/(CC21-CA21) -> 0 | CF21: =CG20 -> 0.00052266667 | CG21: 0 | CH21: =(CF21+CG21-2*(CD21-CB21)/(CC21-CA21))/(CC21-CA21)^2 -> 6.4169755e-08 | CI21: =((CD21-CB21)/(CC21-CA21) - CF21 - CH21*(CC21^2 + CA21*CC21 - 2*CA21^2))/(CC21-CA21) -> -1.3459606e-05 | CJ21: =CF21-2*CI21*CA21 - 3*CH21*CA21^2 -> 0.00076682857 | CK21: =CB21 -CH21*CA21^3 - CI21*CA21^2 - CJ21*CA21 -> 0.024880782 | CN21: =$A21 -> 9.75 | CO21: =$B21 -> 0.031137333 | CP21: 100 | CQ21: =CO21 -> 0.031137333 | CR21: =(CQ21-CO21)/(CP21-CN21) -> 0 | CS21: =CT20 -> 0.000506 | CT21: 0 | CU21: =(CS21+CT21-2*(CQ21-CO21)/(CP21-CN21))/(CP21-CN21)^2 -> 6.2123526e-08 | CV21: =((CQ21-CO21)/(CP21-CN21) - CS21 - CU21*(CP21^2 + CN21*CP21 - 2*CN21^2))/(CP21-CN21) -> -1.303041e-05 | CW21: =CS21-2*CV21*CN21 - 3*CU21*CN21^2 -> 0.00074237613 | CX21: =CO21 -CU21*CN21^3 - CV21*CN21^2 - CW21*CN21 -> 0.02508029 | DA21: =$A21 -> 9.75 | DB21: =$B21+CZ13 -> 0.031237333 | DC21: 100 | DD21: =DB21 -> 0.031237333 | DE21: =(DD21-DB21)/(DC21-DA21) -> 0 | DF21: =DG20 -> 0.00053933333 | DG21: 0 | DH21: =(DF21+DG21-2*(DD21-DB21)/(DC21-DA21))/(DC21-DA21)^2 -> 6.6215985e-08 | DI21: =((DD21-DB21)/(DC21-DA21) - DF21 - DH21*(DC21^2 + DA21*DC21 - 2*DA21^2))/(DC21-DA21) -> -1.3888803e-05 | DJ21: =DF21-2*DI21*DA21 - 3*DH21*DA21^2 -> 0.00079128102 | DK21: =DB21 -DH21*DA21^3 - DI21*DA21^2 - DJ21*DA21 -> 0.024781275
A23: {=TRANSPOSE($A$2:$A$9)} -> 3M Fixing | B23: 1Y Swap | C23: 2Y Swap | D23: 3Y Swap | E23: 4Y Swap | F23: 5Y Swap | G23: 7Y Swap | H23: 10Y Swap | N23: {=TRANSPOSE($A$2:$A$9)} -> 3M Fixing | O23: 1Y Swap | P23: 2Y Swap | Q23: 3Y Swap | R23: 4Y Swap | S23: 5Y Swap | T23: 7Y Swap | U23: 10Y Swap | AA23: {=TRANSPOSE($A$2:$A$9)} -> 3M Fixing | AB23: 1Y Swap | AC23: 2Y Swap | AD23: 3Y Swap | AE23: 4Y Swap | AF23: 5Y Swap | AG23: 7Y Swap | AH23: 10Y Swap | AN23: {=TRANSPOSE($A$2:$A$9)} -> 3M Fixing | AO23: 1Y Swap | AP23: 2Y Swap | AQ23: 3Y Swap | AR23: 4Y Swap | AS23: 5Y Swap | AT23: 7Y Swap | AU23: 10Y Swap | BA23: {=TRANSPOSE($A$2:$A$9)} -> 3M Fixing | BB23: 1Y Swap | BC23: 2Y Swap | BD23: 3Y Swap | BE23: 4Y Swap | BF23: 5Y Swap | BG23: 7Y Swap | BH23: 10Y Swap | BN23: {=TRANSPOSE($A$2:$A$9)} -> 3M Fixing | BO23: 1Y Swap | BP23: 2Y Swap | BQ23: 3Y Swap | BR23: 4Y Swap | BS23: 5Y Swap | BT23: 7Y Swap | BU23: 10Y Swap | CA23: {=TRANSPOSE($A$2:$A$9)} -> 3M Fixing | CB23: 1Y Swap | CC23: 2Y Swap | CD23: 3Y Swap | CE23: 4Y Swap | CF23: 5Y Swap | CG23: 7Y Swap | CH23: 10Y Swap | CN23: {=TRANSPOSE($A$2:$A$9)} -> 3M Fixing | CO23: 1Y Swap | CP23: 2Y Swap | CQ23: 3Y Swap | CR23: 4Y Swap | CS23: 5Y Swap | CT23: 7Y Swap | CU23: 10Y Swap | DA23: {=TRANSPOSE($A$2:$A$9)} -> 3M Fixing | DB23: 1Y Swap | DC23: 2Y Swap | DD23: 3Y Swap | DE23: 4Y Swap | DF23: 5Y Swap | DG23: 7Y Swap | DH23: 10Y Swap
A24: =G27 -> 0.0253 | B24: =SUM(I28:I31)/SUM(J28:J31)*$F$6 -> 0.023402278 | C24: =SUM(I28:I35)/SUM(J28:J35)*$F$6 -> 0.02300636 | D24: =SUM(I28:I39)/SUM(J28:J39)*$F$6 -> 0.023760499 | E24: =SUM(I28:I43)/SUM(J28:J43)*$F$6 -> 0.024366345 | F24: =SUM(I28:I47)/SUM(J28:J47)*$F$6 -> 0.024957821 | G24: =SUM(I28:I55)/SUM(J28:J55)*$F$6 -> 0.025852603 | H24: =SUM(I28:I67)/SUM(J28:J67)*$F$6 -> 0.026982618 | N24: =T27 -> 0.0254 | O24: =SUM(V28:V31)/SUM(W28:W31)*$F$6 -> 0.023453138 | P24: =SUM(V28:V35)/SUM(W28:W35)*$F$6 -> 0.023032073 | Q24: =SUM(V28:V39)/SUM(W28:W39)*$F$6 -> 0.023777848 | R24: =SUM(V28:V43)/SUM(W28:W43)*$F$6 -> 0.024379518 | S24: =SUM(V28:V47)/SUM(W28:W47)*$F$6 -> 0.024968494 | T24: =SUM(V28:V55)/SUM(W28:W55)*$F$6 -> 0.025860428 | U24: =SUM(V28:V67)/SUM(W28:W67)*$F$6 -> 0.026988319 | AA24: =AG27 -> 0.0253 | AB24: =SUM(AI28:AI31)/SUM(AJ28:AJ31)*$F$6 -> 0.02345317 | AC24: =SUM(AI28:AI35)/SUM(AJ28:AJ35)*$F$6 -> 0.02305292 | AD24: =SUM(AI28:AI39)/SUM(AJ28:AJ39)*$F$6 -> 0.023790609 | AE24: =SUM(AI28:AI43)/SUM(AJ28:AJ43)*$F$6 -> 0.024389202 | AF24: =SUM(AI28:AI47)/SUM(AJ28:AJ47)*$F$6 -> 0.024976336 | AG24: =SUM(AI28:AI55)/SUM(AJ28:AJ55)*$F$6 -> 0.025866172 | AH24: =SUM(AI28:AI67)/SUM(AJ28:AJ67)*$F$6 -> 0.0269925 | AN24: =AT27 -> 0.0253 | AO24: =SUM(AV28:AV31)/SUM(AW28:AW31)*$F$6 -> 0.023402278 | AP24: =SUM(AV28:AV35)/SUM(AW28:AW35)*$F$6 -> 0.023037792 | AQ24: =SUM(AV28:AV39)/SUM(AW28:AW39)*$F$6 -> 0.023795396 | AR24: =SUM(AV28:AV43)/SUM(AW28:AW43)*$F$6 -> 0.024391863 | AS24: =SUM(AV28:AV47)/SUM(AW28:AW47)*$F$6 -> 0.02497848 | AT24: =SUM(AV28:AV55)/SUM(AW28:AW55)*$F$6 -> 0.02586773 | AU24: =SUM(AV28:AV67)/SUM(AW28:AW67)*$F$6 -> 0.026993623 | BA24: =BG27 -> 0.0253 | BB24: =SUM(BI28:BI31)/SUM(BJ28:BJ31)*$F$6 -> 0.023402278 | BC24: =SUM(BI28:BI35)/SUM(BJ28:BJ35)*$F$6 -> 0.023004395 | BD24: =SUM(BI28:BI39)/SUM(BJ28:BJ39)*$F$6 -> 0.023781152 | BE24: =SUM(BI28:BI43)/SUM(BJ28:BJ43)*$F$6 -> 0.02439215 | BF24: =SUM(BI28:BI47)/SUM(BJ28:BJ47)*$F$6 -> 0.024977943 | BG24: =SUM(BI28:BI55)/SUM(BJ28:BJ55)*$F$6 -> 0.025867323 | BH24: =SUM(BI28:BI67)/SUM(BJ28:BJ67)*$F$6 -> 0.026993314 | BN24: =BT27 -> 0.0253 | BO24: =SUM(BV28:BV31)/SUM(BW28:BW31)*$F$6 -> 0.023402278 | BP24: =SUM(BV28:BV35)/SUM(BW28:BW35)*$F$6 -> 0.02300636 | BQ24: =SUM(BV28:BV39)/SUM(BW28:BW39)*$F$6 -> 0.023759207 | BR24: =SUM(BV28:BV43)/SUM(BW28:BW43)*$F$6 -> 0.024381631 | BS24: =SUM(BV28:BV47)/SUM(BW28:BW47)*$F$6 -> 0.024978185 | BT24: =SUM(BV28:BV55)/SUM(BW28:BW55)*$F$6 -> 0.025865241 | BU24: =SUM(BV28:BV67)/SUM(BW28:BW67)*$F$6 -> 0.026991793 | CA24: =CG27 -> 0.0253 | CB24: =SUM(CI28:CI31)/SUM(CJ28:CJ31)*$F$6 -> 0.023402278 | CC24: =SUM(CI28:CI35)/SUM(CJ28:CJ35)*$F$6 -> 0.02300636 | CD24: =SUM(CI28:CI39)/SUM(CJ28:CJ39)*$F$6 -> 0.023760499 | CE24: =SUM(CI28:CI43)/SUM(CJ28:CJ43)*$F$6 -> 0.024365388 | CF24: =SUM(CI28:CI47)/SUM(CJ28:CJ47)*$F$6 -> 0.0249695 | CG24: =SUM(CI28:CI55)/SUM(CJ28:CJ55)*$F$6 -> 0.025875353 | CH24: =SUM(CI28:CI67)/SUM(CJ28:CJ67)*$F$6 -> 0.026997371 | CN24: =CT27 -> 0.0253 | CO24: =SUM(CV28:CV31)/SUM(CW28:CW31)*$F$6 -> 0.023402278 | CP24: =SUM(CV28:CV35)/SUM(CW28:CW35)*$F$6 -> 0.02300636 | CQ24: =SUM(CV28:CV39)/SUM(CW28:CW39)*$F$6 -> 0.023760499 | CR24: =SUM(CV28:CV43)/SUM(CW28:CW43)*$F$6 -> 0.024366345 | CS24: =SUM(CV28:CV47)/SUM(CW28:CW47)*$F$6 -> 0.024957444 | CT24: =SUM(CV28:CV55)/SUM(CW28:CW55)*$F$6 -> 0.025868247 | CU24: =SUM(CV28:CV67)/SUM(CW28:CW67)*$F$6 -> 0.027008482 | DA24: =DG27 -> 0.0253 | DB24: =SUM(DI28:DI31)/SUM(DJ28:DJ31)*$F$6 -> 0.023402278 | DC24: =SUM(DI28:DI35)/SUM(DJ28:DJ35)*$F$6 -> 0.02300636 | DD24: =SUM(DI28:DI39)/SUM(DJ28:DJ39)*$F$6 -> 0.023760499 | DE24: =SUM(DI28:DI43)/SUM(DJ28:DJ43)*$F$6 -> 0.024366345 | DF24: =SUM(DI28:DI47)/SUM(DJ28:DJ47)*$F$6 -> 0.024957821 | DG24: =SUM(DI28:DI55)/SUM(DJ28:DJ55)*$F$6 -> 0.025851862 | DH24: =SUM(DI28:DI67)/SUM(DJ28:DJ67)*$F$6 -> 0.026996828
A26: Years | B26: Left X | C26: a | D26: b | E26: c | F26: d | G26: Euribor | H26: Disc Fact | I26: Float PV | J26: Fixed PV | N26: Years | O26: Left X | P26: a | Q26: b | R26: c | S26: d | T26: Euribor | U26: Disc Fact | V26: Float PV | W26: Fixed PV | AA26: Years | AB26: Left X | AC26: a | AD26: b | AE26: c | AF26: d | AG26: Euribor | AH26: Disc Fact | AI26: Float PV | AJ26: Fixed PV | AN26: Years | AO26: Left X | AP26: a | AQ26: b | AR26: c | AS26: d | AT26: Euribor | AU26: Disc Fact | AV26: Float PV | AW26: Fixed PV | BA26: Years | BB26: Left X | BC26: a | BD26: b | BE26: c | BF26: d | BG26: Euribor | BH26: Disc Fact | BI26: Float PV | BJ26: Fixed PV | BN26: Years | BO26: Left X | BP26: a | BQ26: b | BR26: c | BS26: d | BT26: Euribor | BU26: Disc Fact | BV26: Float PV | BW26: Fixed PV | CA26: Years | CB26: Left X | CC26: a | CD26: b | CE26: c | CF26: d | CG26: Euribor | CH26: Disc Fact | CI26: Float PV | CJ26: Fixed PV | CN26: Years | CO26: Left X | CP26: a | CQ26: b | CR26: c | CS26: d | CT26: Euribor | CU26: Disc Fact | CV26: Float PV | CW26: Fixed PV | DA26: Years | DB26: Left X | DC26: a | DD26: b | DE26: c | DF26: d | DG26: Euribor | DH26: Disc Fact | DI26: Float PV | DJ26: Fixed PV
