Workbook

Sheet Random
A1: LRG Parameters | D1: State | E1: U(0, 1) | F1: N(0, 1) | H1: Stat | I1: Sample | J1: True N(0,1)
A2: Seed | B2: 1 | D2: =MOD(B2*B3*B4,B5) -> 1673663072 | E2: {=D2:D10001/(B5-1)} -> 0.7793601 | F2: {=_xlfn.NORM.INV(E2:E10001,0,1)} -> 0.77003388 | H2: Mean | I2: =AVERAGE(F2:F10001) -> -0.0026194203 | J2: 0
A3: Seed Mult | B3: 10000000 | D3: =MOD(D2*$B$4,$B$5) -> 1055348372 | E3: 0.49143488 | F3: -0.021471217 | H3: Std Dev | I3: =_xlfn.STDEV.S(F2:F10001) -> 0.99709475 | J3: 1
A4: G | B4: 48271 | D4: =MOD(D3*$B$4,$B$5) -> 114190678 | E4: 0.053174178 | F4: -1.6148261 | H4: Skewness | I4: =SKEW(F2:F10001) -> 0.030300043 | J4: 0
A5: N | B5: =2^31-1 -> 2147483647 | D5: =MOD(D4*$B$4,$B$5) -> 1655179536 | E5: 0.77075303 | F5: 0.74132908 | H5: Ex. Kurtosis | I5: =KURT(F2:F10001) -> -0.029722525 | J5: 0
D6: =MOD(D5*$B$4,$B$5) -> 42295621 | E6: 0.019695433 | F6: -2.0600803
D7: =MOD(D6*$B$4,$B$5) -> 1542456641 | E7: 0.71826235 | F7: 0.57768722 | H7: Percentile | I7: Sample | J7: True N(0,1)
D8: =MOD(D7*$B$4,$B$5) -> 518992574 | E8: 0.24167475 | F8: -0.70092551 | H8: 0.995 | I8: =PERCENTILE(F$2:F$10001,H8) -> 2.5658225 | J8: =_xlfn.NORM.INV(H8,0,1) -> 2.5758293
D9: =MOD(D8*$B$4,$B$5) -> 1893797299 | E9: 0.88186809 | F9: 1.1843771 | H9: 0.975 | I9: =PERCENTILE(F$2:F$10001,H9) -> 1.9717848 | J9: =_xlfn.NORM.INV(H9,0,1) -> 1.959964
D10: =MOD(D9*$B$4,$B$5) -> 1405534533 | E10: 0.65450302 | F10: 0.39750655 | H10: 0.95 | I10: =PERCENTILE(F$2:F$10001,H10) -> 1.6532261 | J10: =_xlfn.NORM.INV(H10,0,1) -> 1.6448536
D11: =MOD(D10*$B$4,$B$5) -> 1106582772 | E11: 0.51529276 | F11: 0.038342654 | H11: 0.75 | I11: =PERCENTILE(F$2:F$10001,H11) -> 0.65856164 | J11: =_xlfn.NORM.INV(H11,0,1) -> 0.67448975
D12: =MOD(D11*$B$4,$B$5) -> 1496235381 | E12: 0.69673889 | F12: 0.51504409 | H12: 0.5 | I12: =PERCENTILE(F$2:F$10001,H12) -> 0.00089039161 | J12: =_xlfn.NORM.INV(H12,0,1) -> 0
D13: =MOD(D12*$B$4,$B$5) -> 608060347 | E13: 0.28315016 | F13: -0.57350867 | H13: 0.25 | I13: =PERCENTILE(F$2:F$10001,H13) -> -0.67751148 | J13: =_xlfn.NORM.INV(H13,0,1) -> -0.67448975
D14: =MOD(D13*$B$4,$B$5) -> 2022006488 | E14: 0.94157015 | F14: 1.5680918 | H14: 0.05 | I14: =PERCENTILE(F$2:F$10001,H14) -> -1.6277633 | J14: =_xlfn.NORM.INV(H14,0,1) -> -1.6448536
D15: =MOD(D14*$B$4,$B$5) -> 1143426098 | E15: 0.53244927 | F15: 0.081428152 | H15: 0.025 | I15: =PERCENTILE(F$2:F$10001,H15) -> -1.9576943 | J15: =_xlfn.NORM.INV(H15,0,1) -> -1.959964
D16: =MOD(D15*$B$4,$B$5) -> 1843965011 | E16: 0.85866312 | F16: 1.0743323 | H16: 0.005 | I16: =PERCENTILE(F$2:F$10001,H16) -> -2.4923402 | J16: =_xlfn.NORM.INV(H16,0,1) -> -2.5758293
D17: =MOD(D16*$B$4,$B$5) -> 1132845125 | E17: 0.52752212 | F17: 0.069042537
D18: =MOD(D17*$B$4,$B$5) -> 43441667 | E18: 0.020229103 | F18: -2.04904
D19: =MOD(D18*$B$4,$B$5) -> 1028668285 | E19: 0.479011 | F19: -0.05263592
D20: =MOD(D19*$B$4,$B$5) -> 729899301 | E20: 0.33988585 | F20: -0.41277469
D21: =MOD(D20*$B$4,$B$5) -> 1352445889 | E21: 0.62978169 | F21: 0.33127521
D22: =MOD(D21*$B$4,$B$5) -> 412639119 | E22: 0.19215006 | F22: -0.87000051
D23: =MOD(D22*$B$4,$B$5) -> 592087324 | E23: 0.27571215 | F23: -0.59562722
D24: =MOD(D23*$B$4,$B$5) -> 1934842528 | E24: 0.90098126 | F24: 1.287163
D25: =MOD(D24*$B$4,$B$5) -> 572377411 | E25: 0.266534 | F25: -0.62332952
D26: =MOD(D25*$B$4,$B$5) -> 1852887726 | E26: 0.86281808 | F26: 1.0930683
D27: =MOD(D26*$B$4,$B$5) -> 197007843 | E27: 0.091738926 | F27: -1.3301227
D28: =MOD(D27*$B$4,$B$5) -> 708000537 | E28: 0.32968844 | F28: -0.44077363
... D10001: =MOD(D10000*$B$4,$B$5) -> 21635367 | E10001: 0.010074753 | F10001: -2.3235522

Sheet Vanilla Call
A1: Option Parameters | F1: N(0, 1) | G1: S(T) | H1: Payoff | J1: Seed Variance
A2: Current Price | B2: S(0) | C2: 100 | F2: {=Random!F2:F10001} -> 0.77003388 | G2: {=C2 * EXP((C5 - C6 - C7*C7/2)*C4 + F2:F10001*C7*SQRT(C4))} -> 106.39087 | H2: =MAX(G2-$C$3,0) -> 5.3908741 | J2: Seed | K2: Monte-Carlo Call
A3: Strike Price | B3: K | C3: 101 | F3: -0.021471217 | G3: 100.59997 | H3: =MAX(G3-$C$3,0) -> 0 | J3: 1 | K3: 2.8044093
A4: Maturity, Years | B4: T | C4: 0.5 | F4: -1.6148261 | G4: 89.880835 | H4: =MAX(G4-$C$3,0) -> 0 | J4: 2 | K4: 2.794968
A5: Risk-Free Rate | B5: r | C5: 0.02 | F5: 0.74132908 | G5: 106.17515 | H5: =MAX(G5-$C$3,0) -> 5.1751478 | J5: 3 | K5: 2.8177405
A6: Dividend Yield | B6: q | C6: 0 | F6: -2.0600803 | G6: 87.09509 | H6: =MAX(G6-$C$3,0) -> 0 | J6: 4 | K6: 2.8516889
A7: Volatility | B7: sigma | C7: 0.1 | F7: 0.57768722 | G7: 104.95365 | H7: =MAX(G7-$C$3,0) -> 3.9536518 | J7: 5 | K7: 2.8695401
F8: -0.70092551 | G8: 95.880945 | H8: =MAX(G8-$C$3,0) -> 0 | J8: 6 | K8: 2.7616124
A9: Disc Factor | B9: =EXP(-$C$5*$C$4) -> 0.99004983 | F9: 1.1843771 | G9: 109.55408 | H9: =MAX(G9-$C$3,0) -> 8.5540784 | J9: 7 | K9: 2.8638503
A10: Black-Scholes Call | B10: =C2*EXP(-C6*C4)*_xlfn.NORM.DIST((LN(C2/C3) + (C5 - C6 + C7*C7/2)*C4) / (C7*SQRT(C4)),0,1,1) - C3*EXP(-C5*C4)*_xlfn.NORM.DIST((LN(C2/C3) + (C5 - C6 - C7*C7/2)*C4) / (C7*SQRT(C4)),0,1,1) -> 2.8227744 | F10: 0.39750655 | G10: 103.62495 | H10: =MAX(G10-$C$3,0) -> 2.6249513 | J10: 8 | K10: 2.7893657
A11: Monte-Carlo Call | B11: =AVERAGE(H2:H10001) * B9 -> 2.8044093 | F11: 0.038342654 | G11: 101.02635 | H11: =MAX(G11-$C$3,0) -> 0.026354763 | J11: 9 | K11: 2.7771472
A12: Std Dev | B12: =_xlfn.STDEV.S(H2:H10001) / SQRT(COUNT(H2:H10001)) * B9 -> 0.043110168 | C12: =B12/B11 -> 0.015372281 | F12: 0.51504409 | G12: 104.48978 | H12: =MAX(G12-$C$3,0) -> 3.4897837 | J12: 10 | K12: 2.9033247
A13: Difference | B13: =B11-B10 -> -0.018365054 | C13: =B11/B10-1 -> -0.0065060298 | F13: -0.57350867 | G13: 96.74871 | H13: =MAX(G13-$C$3,0) -> 0 | J13: 11 | K13: 2.8198875
F14: 1.5680918 | G14: 112.56727 | H14: =MAX(G14-$C$3,0) -> 11.567272 | J14: 12 | K14: 2.8494032
A15: Confidence | B15: N(0, 1) | C15: Left | D15: Right | F15: 0.081428152 | G15: 101.33461 | H15: =MAX(G15-$C$3,0) -> 0.33461147 | J15: 13 | K15: 2.8166557
A16: 0.95 | B16: =_xlfn.NORM.INV((1+A16)/2, 0, 1) -> 1.959964 | C16: =$B$11 - $B$12 * B16 -> 2.7199149 | D16: =$B$11 + $B$12 * B16 -> 2.8889037 | F16: 1.0743323 | G16: 108.70491 | H16: =MAX(G16-$C$3,0) -> 7.704909 | J16: 14 | K16: 2.8344509
A17: 0.99 | B17: =_xlfn.NORM.INV((1+A17)/2, 0, 1) -> 2.5758293 | C17: =$B$11 - $B$12 * B17 -> 2.6933649 | D17: =$B$11 + $B$12 * B17 -> 2.9154538 | F17: 0.069042537 | G17: 101.2459 | H17: =MAX(G17-$C$3,0) -> 0.24590195 | J17: 15 | K17: 2.8018658
A18: 0.999 | B18: =_xlfn.NORM.INV((1+A18)/2, 0, 1) -> 3.2905267 | C18: =$B$11 - $B$12 * B18 -> 2.6625542 | D18: =$B$11 + $B$12 * B18 -> 2.9462645 | F18: -2.04904 | G18: 87.163109 | H18: =MAX(G18-$C$3,0) -> 0 | J18: 16 | K18: 2.7311578
F19: -0.05263592 | G19: 100.37852 | H19: =MAX(G19-$C$3,0) -> 0 | J19: 17 | K19: 2.7892804
A20: Req. Accuracy | B20: 0.01 | F20: -0.41277469 | G20: 97.854591 | H20: =MAX(G20-$C$3,0) -> 0 | J20: 18 | K20: 2.8080448
A21: Req. Conf. Level | B21: 0.999 | F21: 0.33127521 | G21: 103.14078 | H21: =MAX(G21-$C$3,0) -> 2.1407831 | J21: 19 | K21: 2.7669045
A22: Req. N(0, 1) | B22: =_xlfn.NORM.INV((1+B21)/2, 0, 1) -> 3.2905267 | F22: -0.87000051 | G22: 94.741474 | H22: =MAX(G22-$C$3,0) -> 0 | J22: 20 | K22: 2.8835189
A23: Req. Simulations | B23: =(2*B12*B22*SQRT(COUNT(H2:H10001))/B20)^2 -> 8049154.7 | F23: -0.59562722 | G23: 96.597512 | H23: =MAX(G23-$C$3,0) -> 0
F24: 1.287163 | G24: 110.35322 | H24: =MAX(G24-$C$3,0) -> 9.3532248 | J24: Mean | K24: =AVERAGE(K3:K22) -> 2.8167408
F25: -0.62332952 | G25: 96.408477 | H25: =MAX(G25-$C$3,0) -> 0 | J25: Std Dev | K25: =_xlfn.STDEV.S(K3:K22) -> 0.043780122
F26: 1.0930683 | G26: 108.84902 | H26: =MAX(G26-$C$3,0) -> 7.8490199 | J26: Std Dev, % | K26: =K25/K24 -> 0.015542829
F27: -1.3301227 | G27: 91.708614 | H27: =MAX(G27-$C$3,0) -> 0
F28: -0.44077363 | G28: 97.661047 | H28: =MAX(G28-$C$3,0) -> 0
F29: -0.27732365 | G29: 98.796328 | H29: =MAX(G29-$C$3,0) -> 0
F30: 0.40161095 | G30: 103.65503 | H30: =MAX(G30-$C$3,0) -> 2.6550302
F31: -0.022358811 | G31: 100.59365 | H31: =MAX(G31-$C$3,0) -> 0
F32: 1.8063811 | G32: 114.48006 | H32: =MAX(G32-$C$3,0) -> 13.480055
F33: 0.79484663 | G33: 106.5777 | H33: =MAX(G33-$C$3,0) -> 5.5777036
F34: -0.47784146 | G34: 97.405404 | H34: =MAX(G34-$C$3,0) -> 0
F35: -1.6202444 | G35: 89.846405 | H35: =MAX(G35-$C$3,0) -> 0
F36: 0.16814432 | G36: 101.95788 | H36: =MAX(G36-$C$3,0) -> 0.95787977
F37: -0.46930818 | G37: 97.464196 | H37: =MAX(G37-$C$3,0) -> 0
F38: 1.6344115 | G38: 113.0964 | H38: =MAX(G38-$C$3,0) -> 12.096398
... F10001: -2.3235522 | G10001: 85.487506 | H10001: =MAX(G10001-$C$3,0) -> 0

Sheet Asian Call
A1: Option Parameters | F1: N(0, 1) | R1: Step | S1: 0 | T1: 1 | U1: 2 | V1: 3 | W1: 4 | X1: 5 | Y1: 6 | Z1: 7 | AA1: 8 | AB1: 9 | AC1: 10 | AD1: Average | AE1: Payoff
A2: Current Price | B2: S(0) | C2: 100 | F2: Step | G2: 1 | H2: 2 | I2: 3 | J2: 4 | K2: 5 | L2: 6 | M2: 7 | N2: 8 | O2: 9 | P2: 10 | R2: Time | S2: =S1 * $C$4/$C$8 -> 0 | T2: =T1 * $C$4/$C$8 -> 0.05 | U2: =U1 * $C$4/$C$8 -> 0.1 | V2: =V1 * $C$4/$C$8 -> 0.15 | W2: =W1 * $C$4/$C$8 -> 0.2 | X2: =X1 * $C$4/$C$8 -> 0.25 | Y2: =Y1 * $C$4/$C$8 -> 0.3 | Z2: =Z1 * $C$4/$C$8 -> 0.35 | ... AC2: =AC1 * $C$4/$C$8 -> 0.5
A3: Strike Price | B3: K | C3: 101 | F3: 1 | G3: =INDEX(Random!$F$2:$F$10001, ($F3-1)*10+G$2) -> 0.77003388 | H3: =INDEX(Random!$F$2:$F$10001, ($F3-1)*10+H$2) -> -0.021471217 | I3: =INDEX(Random!$F$2:$F$10001, ($F3-1)*10+I$2) -> -1.6148261 | J3: =INDEX(Random!$F$2:$F$10001, ($F3-1)*10+J$2) -> 0.74132908 | K3: =INDEX(Random!$F$2:$F$10001, ($F3-1)*10+K$2) -> -2.0600803 | L3: =INDEX(Random!$F$2:$F$10001, ($F3-1)*10+L$2) -> 0.57768722 | M3: =INDEX(Random!$F$2:$F$10001, ($F3-1)*10+M$2) -> -0.70092551 | N3: =INDEX(Random!$F$2:$F$10001, ($F3-1)*10+N$2) -> 1.1843771 | ... P3: =INDEX(Random!$F$2:$F$10001, ($F3-1)*10+P$2) -> 0.038342654 | R3: 1 | S3: {=$C$2} -> 100 | T3: {=S3:S1002 * EXP(($C$5 - $C$6 - $C$7*$C$7/2)*(T$2-S$2) + G3:G1002 * $C$7 * SQRT(T$2-S$2))} -> 102.66132 | U3: {=T3:T1002 * EXP(($C$5 - $C$6 - $C$7*$C$7/2)*(U$2-T$2) + H3:H1002 * $C$7 * SQRT(U$2-T$2))} -> 102.6323 | V3: {=U3:U1002 * EXP(($C$5 - $C$6 - $C$7*$C$7/2)*(V$2-U$2) + I3:I1002 * $C$7 * SQRT(V$2-U$2))} -> 97.263844 | W3: {=V3:V1002 * EXP(($C$5 - $C$6 - $C$7*$C$7/2)*(W$2-V$2) + J3:J1002 * $C$7 * SQRT(W$2-V$2))} -> 99.756255 | X3: {=W3:W1002 * EXP(($C$5 - $C$6 - $C$7*$C$7/2)*(X$2-W$2) + K3:K1002 * $C$7 * SQRT(X$2-W$2))} -> 93.136864 | Y3: {=X3:X1002 * EXP(($C$5 - $C$6 - $C$7*$C$7/2)*(Y$2-X$2) + L3:L1002 * $C$7 * SQRT(Y$2-X$2))} -> 95.000655 | Z3: {=Y3:Y1002 * EXP(($C$5 - $C$6 - $C$7*$C$7/2)*(Z$2-Y$2) + M3:M1002 * $C$7 * SQRT(Z$2-Y$2))} -> 92.833868 | AA3: {=Z3:Z1002 * EXP(($C$5 - $C$6 - $C$7*$C$7/2)*(AA$2-Z$2) + N3:N1002 * $C$7 * SQRT(AA$2-Z$2))} -> 96.638213 | ... AC3: {=AB3:AB1002 * EXP(($C$5 - $C$6 - $C$7*$C$7/2)*(AC$2-AB$2) + P3:P1002 * $C$7 * SQRT(AC$2-AB$2))} -> 98.147168 | AD3: =AVERAGE(T3:AC3) -> 97.604864 | AE3: =MAX(AD3-$C$3, 0) -> 0
A4: Maturity, Years | B4: T | C4: 0.5 | F4: 2 | G4: =INDEX(Random!$F$2:$F$10001, ($F4-1)*10+G$2) -> 0.51504409 | H4: =INDEX(Random!$F$2:$F$10001, ($F4-1)*10+H$2) -> -0.57350867 | I4: =INDEX(Random!$F$2:$F$10001, ($F4-1)*10+I$2) -> 1.5680918 | J4: =INDEX(Random!$F$2:$F$10001, ($F4-1)*10+J$2) -> 0.081428152 | K4: =INDEX(Random!$F$2:$F$10001, ($F4-1)*10+K$2) -> 1.0743323 | L4: =INDEX(Random!$F$2:$F$10001, ($F4-1)*10+L$2) -> 0.069042537 | M4: =INDEX(Random!$F$2:$F$10001, ($F4-1)*10+M$2) -> -2.04904 | N4: =INDEX(Random!$F$2:$F$10001, ($F4-1)*10+N$2) -> -0.05263592 | ... P4: =INDEX(Random!$F$2:$F$10001, ($F4-1)*10+P$2) -> 0.33127521 | R4: 2 | S4: 100 | T4: 101.78704 | U4: 99.891463 | V4: 105.33198 | W4: 105.66628 | X4: 109.59125 | Y4: 109.8934 | Z4: 102.63935 | AA4: 102.50314 | AB4: 101.13801 | AC4: 102.3128 | AD4: =AVERAGE(T4:AC4) -> 104.07547 | AE4: =MAX(AD4-$C$3, 0) -> 3.075471
A5: Risk-Free Rate | B5: r | C5: 0.02 | F5: 3 | G5: =INDEX(Random!$F$2:$F$10001, ($F5-1)*10+G$2) -> -0.87000051 | H5: =INDEX(Random!$F$2:$F$10001, ($F5-1)*10+H$2) -> -0.59562722 | I5: =INDEX(Random!$F$2:$F$10001, ($F5-1)*10+I$2) -> 1.287163 | J5: =INDEX(Random!$F$2:$F$10001, ($F5-1)*10+J$2) -> -0.62332952 | K5: =INDEX(Random!$F$2:$F$10001, ($F5-1)*10+K$2) -> 1.0930683 | L5: =INDEX(Random!$F$2:$F$10001, ($F5-1)*10+L$2) -> -1.3301227 | M5: =INDEX(Random!$F$2:$F$10001, ($F5-1)*10+M$2) -> -0.44077363 | N5: =INDEX(Random!$F$2:$F$10001, ($F5-1)*10+N$2) -> -0.27732365 | ... P5: =INDEX(Random!$F$2:$F$10001, ($F5-1)*10+P$2) -> -0.022358811 | R5: 3 | S5: 100 | T5: 97.166595 | U5: 95.286347 | V5: 99.533752 | W5: 97.517046 | X5: 101.20289 | Y5: 96.829446 | Z5: 95.4502 | AA5: 94.607848 | AB5: 95.932841 | AC5: 95.902872 | AD5: =AVERAGE(T5:AC5) -> 96.942984 | AE5: =MAX(AD5-$C$3, 0) -> 0
A6: Dividend Yield | B6: q | C6: 0 | F6: 4 | G6: =INDEX(Random!$F$2:$F$10001, ($F6-1)*10+G$2) -> 1.8063811 | H6: =INDEX(Random!$F$2:$F$10001, ($F6-1)*10+H$2) -> 0.79484663 | I6: =INDEX(Random!$F$2:$F$10001, ($F6-1)*10+I$2) -> -0.47784146 | J6: =INDEX(Random!$F$2:$F$10001, ($F6-1)*10+J$2) -> -1.6202444 | K6: =INDEX(Random!$F$2:$F$10001, ($F6-1)*10+K$2) -> 0.16814432 | L6: =INDEX(Random!$F$2:$F$10001, ($F6-1)*10+L$2) -> -0.46930818 | M6: =INDEX(Random!$F$2:$F$10001, ($F6-1)*10+M$2) -> 1.6344115 | N6: =INDEX(Random!$F$2:$F$10001, ($F6-1)*10+N$2) -> -2.1378119 | ... P6: =INDEX(Random!$F$2:$F$10001, ($F6-1)*10+P$2) -> -1.1724312 | R6: 4 | S6: 100 | T6: 106.29259 | U6: 109.21223 | V6: 107.52283 | W6: 101.88004 | X6: 102.50108 | Y6: 100.94439 | Z6: 106.67929 | AA6: 99.341178 | AB6: 96.335346 | AC6: 92.661054 | AD6: =AVERAGE(T6:AC6) -> 102.337 | AE6: =MAX(AD6-$C$3, 0) -> 1.3370024
A7: Volatility | B7: sigma | C7: 0.15 | F7: 5 | G7: =INDEX(Random!$F$2:$F$10001, ($F7-1)*10+G$2) -> -0.72345226 | H7: =INDEX(Random!$F$2:$F$10001, ($F7-1)*10+H$2) -> -0.66277608 | I7: =INDEX(Random!$F$2:$F$10001, ($F7-1)*10+I$2) -> -1.0884108 | J7: =INDEX(Random!$F$2:$F$10001, ($F7-1)*10+J$2) -> -0.29335385 | K7: =INDEX(Random!$F$2:$F$10001, ($F7-1)*10+K$2) -> -0.59961662 | L7: =INDEX(Random!$F$2:$F$10001, ($F7-1)*10+L$2) -> 0.35744114 | M7: =INDEX(Random!$F$2:$F$10001, ($F7-1)*10+M$2) -> -1.5645362 | N7: =INDEX(Random!$F$2:$F$10001, ($F7-1)*10+N$2) -> 0.12103896 | ... P7: =INDEX(Random!$F$2:$F$10001, ($F7-1)*10+P$2) -> 0.30477959 | R7: 5 | S7: 100 | T7: 97.645381 | U7: 95.540446 | V7: 92.155813 | W7: 91.293435 | X7: 89.514858 | Y7: 90.634149 | Z7: 86.03829 | AA7: 86.426099 | AB7: 88.081304 | AC7: 89.025284 | AD7: =AVERAGE(T7:AC7) -> 90.635506 | AE7: =MAX(AD7-$C$3, 0) -> 0
A8: Observations | B8: n | C8: 10 | F8: 6 | G8: =INDEX(Random!$F$2:$F$10001, ($F8-1)*10+G$2) -> -1.122036 | H8: =INDEX(Random!$F$2:$F$10001, ($F8-1)*10+H$2) -> 0.88318593 | I8: =INDEX(Random!$F$2:$F$10001, ($F8-1)*10+I$2) -> 0.35417352 | J8: =INDEX(Random!$F$2:$F$10001, ($F8-1)*10+J$2) -> 2.4464606 | K8: =INDEX(Random!$F$2:$F$10001, ($F8-1)*10+K$2) -> 0.86114115 | L8: =INDEX(Random!$F$2:$F$10001, ($F8-1)*10+L$2) -> -0.19836295 | M8: =INDEX(Random!$F$2:$F$10001, ($F8-1)*10+M$2) -> -0.099004086 | N8: =INDEX(Random!$F$2:$F$10001, ($F8-1)*10+N$2) -> -1.603532 | ... P8: =INDEX(Random!$F$2:$F$10001, ($F8-1)*10+P$2) -> 0.36133867 | R8: 6 | S8: 100 | T8: 96.348657 | U8: 99.288913 | V8: 100.5194 | W8: 109.16331 | X8: 112.41148 | Y8: 111.71492 | Z8: 111.39329 | AA8: 105.60656 | AB8: 104.37946 | AC8: 105.69843 | AD8: =AVERAGE(T8:AC8) -> 105.65244 | AE8: =MAX(AD8-$C$3, 0) -> 4.6524422
F9: 7 | G9: =INDEX(Random!$F$2:$F$10001, ($F9-1)*10+G$2) -> -0.19970767 | H9: =INDEX(Random!$F$2:$F$10001, ($F9-1)*10+H$2) -> -1.4556095 | I9: =INDEX(Random!$F$2:$F$10001, ($F9-1)*10+I$2) -> 0.61148664 | J9: =INDEX(Random!$F$2:$F$10001, ($F9-1)*10+J$2) -> 0.39078927 | K9: =INDEX(Random!$F$2:$F$10001, ($F9-1)*10+K$2) -> 0.93897328 | L9: =INDEX(Random!$F$2:$F$10001, ($F9-1)*10+L$2) -> -2.2119055 | M9: =INDEX(Random!$F$2:$F$10001, ($F9-1)*10+M$2) -> -2.2730263 | N9: =INDEX(Random!$F$2:$F$10001, ($F9-1)*10+N$2) -> 0.55360732 | ... P9: =INDEX(Random!$F$2:$F$10001, ($F9-1)*10+P$2) -> -1.0668088 | R9: 7 | S9: 100 | T9: 99.375866 | U9: 94.682024 | V9: 96.686283 | W9: 98.004806 | X9: 101.18476 | Y9: 93.990721 | Z9: 87.129363 | AA9: 88.801186 | AB9: 84.897011 | AC9: 81.94879 | AD9: =AVERAGE(T9:AC9) -> 92.670081 | AE9: =MAX(AD9-$C$3, 0) -> 0
A10: Monte-Carlo Call | B10: =AVERAGE(AE3:AE1002) * EXP(-$C$5*$C$4) -> 2.4705985 | F10: 8 | G10: =INDEX(Random!$F$2:$F$10001, ($F10-1)*10+G$2) -> -1.0046006 | H10: =INDEX(Random!$F$2:$F$10001, ($F10-1)*10+H$2) -> 0.97538474 | I10: =INDEX(Random!$F$2:$F$10001, ($F10-1)*10+I$2) -> 0.0090018173 | J10: =INDEX(Random!$F$2:$F$10001, ($F10-1)*10+J$2) -> 1.0310011 | K10: =INDEX(Random!$F$2:$F$10001, ($F10-1)*10+K$2) -> -1.7661142 | L10: =INDEX(Random!$F$2:$F$10001, ($F10-1)*10+L$2) -> 0.063344635 | M10: =INDEX(Random!$F$2:$F$10001, ($F10-1)*10+M$2) -> 0.085445841 | N10: =INDEX(Random!$F$2:$F$10001, ($F10-1)*10+N$2) -> 1.7481604 | ... P10: =INDEX(Random!$F$2:$F$10001, ($F10-1)*10+P$2) -> 0.16283613 | R10: 8 | S10: 100 | T10: 96.728913 | U10: 99.989507 | V10: 100.06347 | W10: 103.6296 | X10: 97.711889 | Y10: 97.962562 | Z10: 98.286711 | AA10: 104.26768 | AB10: 105.48725 | AC10: 106.11137 | AD10: =AVERAGE(T10:AC10) -> 101.0239 | AE10: =MAX(AD10-$C$3, 0) -> 0.023895192
A11: Std Dev | B11: =_xlfn.STDEV.S(AE3:AE1002)/SQRT(COUNT(AE3:AE1002)) * EXP(-$C$5*$C$4) -> 0.12225369 | C11: =B11/B10 -> 0.049483432 | F11: 9 | G11: =INDEX(Random!$F$2:$F$10001, ($F11-1)*10+G$2) -> -0.029378262 | H11: =INDEX(Random!$F$2:$F$10001, ($F11-1)*10+H$2) -> 0.97048475 | I11: =INDEX(Random!$F$2:$F$10001, ($F11-1)*10+I$2) -> 0.58976956 | J11: =INDEX(Random!$F$2:$F$10001, ($F11-1)*10+J$2) -> -0.082535521 | K11: =INDEX(Random!$F$2:$F$10001, ($F11-1)*10+K$2) -> 1.2152465 | L11: =INDEX(Random!$F$2:$F$10001, ($F11-1)*10+L$2) -> -1.398583 | M11: =INDEX(Random!$F$2:$F$10001, ($F11-1)*10+M$2) -> -0.10982132 | N11: =INDEX(Random!$F$2:$F$10001, ($F11-1)*10+N$2) -> 1.1582604 | ... P11: =INDEX(Random!$F$2:$F$10001, ($F11-1)*10+P$2) -> 0.70316178 | R11: 9 | S11: 100 | T11: 99.945227 | U11: 103.29726 | V11: 105.40708 | W11: 105.16168 | X11: 109.58463 | Y11: 104.60849 | Z11: 104.26948 | AA11: 108.44742 | AB11: 107.36099 | AC11: 109.97128 | AD11: =AVERAGE(T11:AC11) -> 105.80535 | AE11: =MAX(AD11-$C$3, 0) -> 4.8053538
F12: 10 | G12: =INDEX(Random!$F$2:$F$10001, ($F12-1)*10+G$2) -> 0.76118985 | H12: =INDEX(Random!$F$2:$F$10001, ($F12-1)*10+H$2) -> -0.13820517 | I12: =INDEX(Random!$F$2:$F$10001, ($F12-1)*10+I$2) -> -0.040053655 | J12: =INDEX(Random!$F$2:$F$10001, ($F12-1)*10+J$2) -> -0.3075265 | K12: =INDEX(Random!$F$2:$F$10001, ($F12-1)*10+K$2) -> -0.27225431 | L12: =INDEX(Random!$F$2:$F$10001, ($F12-1)*10+L$2) -> 0.41492362 | M12: =INDEX(Random!$F$2:$F$10001, ($F12-1)*10+M$2) -> -0.36779231 | N12: =INDEX(Random!$F$2:$F$10001, ($F12-1)*10+N$2) -> -0.55379921 | ... P12: =INDEX(Random!$F$2:$F$10001, ($F12-1)*10+P$2) -> 2.1907635 | R12: 10 | S12: 100 | T12: 102.63087 | U12: 102.20092 | V12: 102.10838 | W12: 101.10479 | X12: 100.22958 | Y12: 101.6787 | Z12: 100.47603 | AA12: 98.670073 | AB12: 100.88801 | AC12: 108.62798 | AD12: =AVERAGE(T12:AC12) -> 101.86153 | AE12: =MAX(AD12-$C$3, 0) -> 0.86153429
A13: Confidence | B13: N(0, 1) | C13: Left | D13: Right | F13: 11 | G13: =INDEX(Random!$F$2:$F$10001, ($F13-1)*10+G$2) -> 1.219039 | H13: =INDEX(Random!$F$2:$F$10001, ($F13-1)*10+H$2) -> 1.2879173 | I13: =INDEX(Random!$F$2:$F$10001, ($F13-1)*10+I$2) -> 0.27313996 | J13: =INDEX(Random!$F$2:$F$10001, ($F13-1)*10+J$2) -> 0.74485004 | K13: =INDEX(Random!$F$2:$F$10001, ($F13-1)*10+K$2) -> -0.085940683 | L13: =INDEX(Random!$F$2:$F$10001, ($F13-1)*10+L$2) -> 0.11501962 | M13: =INDEX(Random!$F$2:$F$10001, ($F13-1)*10+M$2) -> 0.24858351 | N13: =INDEX(Random!$F$2:$F$10001, ($F13-1)*10+N$2) -> 0.55255614 | ... P13: =INDEX(Random!$F$2:$F$10001, ($F13-1)*10+P$2) -> -0.45403103 | R13: 11 | S13: 100 | T13: 104.21911 | U13: 108.86745 | V13: 109.91749 | W13: 112.74746 | X13: 112.47213 | Y13: 112.95628 | Z13: 113.95186 | AA13: 116.13425 | AB13: 118.43175 | AC13: 116.6929 | AD13: =AVERAGE(T13:AC13) -> 112.63907 | AE13: =MAX(AD13-$C$3, 0) -> 11.639067
A14: 0.95 | B14: =_xlfn.NORM.INV((1+A14)/2, 0, 1) -> 1.959964 | C14: =$B$10 - $B$11 * B14 -> 2.2309857 | D14: =$B$10 + $B$11 * B14 -> 2.7102114 | F14: 12 | G14: =INDEX(Random!$F$2:$F$10001, ($F14-1)*10+G$2) -> -0.24135327 | H14: =INDEX(Random!$F$2:$F$10001, ($F14-1)*10+H$2) -> -0.22884347 | I14: =INDEX(Random!$F$2:$F$10001, ($F14-1)*10+I$2) -> 0.66526098 | J14: =INDEX(Random!$F$2:$F$10001, ($F14-1)*10+J$2) -> -0.68487127 | K14: =INDEX(Random!$F$2:$F$10001, ($F14-1)*10+K$2) -> -1.5313986 | L14: =INDEX(Random!$F$2:$F$10001, ($F14-1)*10+L$2) -> -1.1240584 | M14: =INDEX(Random!$F$2:$F$10001, ($F14-1)*10+M$2) -> -1.3949514 | N14: =INDEX(Random!$F$2:$F$10001, ($F14-1)*10+N$2) -> 0.92567358 | ... P14: =INDEX(Random!$F$2:$F$10001, ($F14-1)*10+P$2) -> 0.17871074 | R14: 12 | S14: 100 | T14: 99.237151 | U14: 98.521452 | V14: 100.78861 | W14: 98.542858 | X14: 93.649996 | Y14: 90.224393 | Z14: 86.137877 | AA14: 88.893122 | AB14: 86.17823 | AC14: 86.734284 | AD14: =AVERAGE(T14:AC14) -> 92.890797 | AE14: =MAX(AD14-$C$3, 0) -> 0
A15: 0.99 | B15: =_xlfn.NORM.INV((1+A15)/2, 0, 1) -> 2.5758293 | C15: =$B$10 - $B$11 * B15 -> 2.1556939 | D15: =$B$10 + $B$11 * B15 -> 2.7855032 | F15: 13 | G15: =INDEX(Random!$F$2:$F$10001, ($F15-1)*10+G$2) -> 0.7144657 | H15: =INDEX(Random!$F$2:$F$10001, ($F15-1)*10+H$2) -> -1.2616514 | I15: =INDEX(Random!$F$2:$F$10001, ($F15-1)*10+I$2) -> 0.99521177 | J15: =INDEX(Random!$F$2:$F$10001, ($F15-1)*10+J$2) -> -0.022583618 | K15: =INDEX(Random!$F$2:$F$10001, ($F15-1)*10+K$2) -> 0.34908956 | L15: =INDEX(Random!$F$2:$F$10001, ($F15-1)*10+L$2) -> 1.7350154 | M15: =INDEX(Random!$F$2:$F$10001, ($F15-1)*10+M$2) -> -1.4400059 | N15: =INDEX(Random!$F$2:$F$10001, ($F15-1)*10+N$2) -> -1.375995 | ... P15: =INDEX(Random!$F$2:$F$10001, ($F15-1)*10+P$2) -> 1.5003575 | R15: 13 | S15: 100 | T15: 102.47016 | U15: 98.267369 | V15: 101.6474 | W15: 101.61488 | X15: 102.85665 | Y15: 109.06761 | Z15: 103.9704 | AA15: 99.324416 | AB15: 100.50031 | AC15: 105.7335 | AD15: =AVERAGE(T15:AC15) -> 102.54527 | AE15: =MAX(AD15-$C$3, 0) -> 1.5452683
A16: 0.999 | B16: =_xlfn.NORM.INV((1+A16)/2, 0, 1) -> 3.2905267 | C16: =$B$10 - $B$11 * B16 -> 2.0683195 | D16: =$B$10 + $B$11 * B16 -> 2.8728776 | F16: 14 | G16: =INDEX(Random!$F$2:$F$10001, ($F16-1)*10+G$2) -> -0.2951963 | H16: =INDEX(Random!$F$2:$F$10001, ($F16-1)*10+H$2) -> -0.53265153 | I16: =INDEX(Random!$F$2:$F$10001, ($F16-1)*10+I$2) -> -1.174597 | J16: =INDEX(Random!$F$2:$F$10001, ($F16-1)*10+J$2) -> -0.5680664 | K16: =INDEX(Random!$F$2:$F$10001, ($F16-1)*10+K$2) -> 2.3552899 | L16: =INDEX(Random!$F$2:$F$10001, ($F16-1)*10+L$2) -> -0.54225975 | M16: =INDEX(Random!$F$2:$F$10001, ($F16-1)*10+M$2) -> 1.9609289 | N16: =INDEX(Random!$F$2:$F$10001, ($F16-1)*10+N$2) -> 1.5952949 | ... P16: =INDEX(Random!$F$2:$F$10001, ($F16-1)*10+P$2) -> -0.22494283 | R16: 14 | S16: 100 | T16: 99.058095 | U16: 97.346651 | V16: 93.626985 | W16: 91.900146 | X16: 99.498139 | Y16: 97.747586 | Z16: 104.43841 | AA16: 110.22711 | AB16: 110.23826 | AC16: 109.45754 | AD16: =AVERAGE(T16:AC16) -> 101.35389 | AE16: =MAX(AD16-$C$3, 0) -> 0.35389326
F17: 15 | G17: =INDEX(Random!$F$2:$F$10001, ($F17-1)*10+G$2) -> 1.6878412 | H17: =INDEX(Random!$F$2:$F$10001, ($F17-1)*10+H$2) -> -2.3806676 | I17: =INDEX(Random!$F$2:$F$10001, ($F17-1)*10+I$2) -> -1.3239593 | J17: =INDEX(Random!$F$2:$F$10001, ($F17-1)*10+J$2) -> 0.087880733 | K17: =INDEX(Random!$F$2:$F$10001, ($F17-1)*10+K$2) -> 0.44977416 | L17: =INDEX(Random!$F$2:$F$10001, ($F17-1)*10+L$2) -> 0.19341983 | M17: =INDEX(Random!$F$2:$F$10001, ($F17-1)*10+M$2) -> -1.006188 | N17: =INDEX(Random!$F$2:$F$10001, ($F17-1)*10+N$2) -> -0.26899436 | ... P17: =INDEX(Random!$F$2:$F$10001, ($F17-1)*10+P$2) -> -1.0613064 | R17: 15 | S17: 100 | T17: 105.87081 | U17: 97.78851 | V17: 93.581961 | W17: 93.899283 | X17: 95.36829 | Y17: 96.031007 | Z17: 92.884804 | AA17: 92.090815 | AB17: 89.364421 | AC17: 86.276981 | AD17: =AVERAGE(T17:AC17) -> 94.315688 | AE17: =MAX(AD17-$C$3, 0) -> 0
A18: Req. Accuracy | B18: 0.1 | F18: 16 | G18: =INDEX(Random!$F$2:$F$10001, ($F18-1)*10+G$2) -> -0.48243008 | H18: =INDEX(Random!$F$2:$F$10001, ($F18-1)*10+H$2) -> -0.50083362 | I18: =INDEX(Random!$F$2:$F$10001, ($F18-1)*10+I$2) -> -0.66994996 | J18: =INDEX(Random!$F$2:$F$10001, ($F18-1)*10+J$2) -> -0.014743541 | K18: =INDEX(Random!$F$2:$F$10001, ($F18-1)*10+K$2) -> 0.2245723 | L18: =INDEX(Random!$F$2:$F$10001, ($F18-1)*10+L$2) -> -1.3505642 | M18: =INDEX(Random!$F$2:$F$10001, ($F18-1)*10+M$2) -> -2.7705825 | N18: =INDEX(Random!$F$2:$F$10001, ($F18-1)*10+N$2) -> -1.6173471 | ... P18: =INDEX(Random!$F$2:$F$10001, ($F18-1)*10+P$2) -> 0.20555348 | R18: 16 | S18: 100 | T18: 98.437959 | U18: 96.840522 | V18: 94.73014 | W18: 94.724739 | X18: 95.482701 | Y18: 91.293837 | Z18: 83.228732 | AA18: 78.868558 | AB18: 79.697016 | AC18: 80.2835 | AD18: =AVERAGE(T18:AC18) -> 89.35877 | AE18: =MAX(AD18-$C$3, 0) -> 0
A19: Req. Conf. Level | B19: 0.95 | F19: 17 | G19: =INDEX(Random!$F$2:$F$10001, ($F19-1)*10+G$2) -> -0.79190254 | H19: =INDEX(Random!$F$2:$F$10001, ($F19-1)*10+H$2) -> -1.4708297 | I19: =INDEX(Random!$F$2:$F$10001, ($F19-1)*10+I$2) -> -0.69430151 | J19: =INDEX(Random!$F$2:$F$10001, ($F19-1)*10+J$2) -> 1.2303847 | K19: =INDEX(Random!$F$2:$F$10001, ($F19-1)*10+K$2) -> -1.2145721 | L19: =INDEX(Random!$F$2:$F$10001, ($F19-1)*10+L$2) -> -1.1348284 | M19: =INDEX(Random!$F$2:$F$10001, ($F19-1)*10+M$2) -> -0.044347735 | N19: =INDEX(Random!$F$2:$F$10001, ($F19-1)*10+N$2) -> 0.70729611 | ... P19: =INDEX(Random!$F$2:$F$10001, ($F19-1)*10+P$2) -> -0.039336575 | R19: 17 | S19: 100 | T19: 97.421455 | U19: 92.772554 | V19: 90.67673 | W19: 94.538449 | X19: 90.804254 | Y19: 87.451148 | Z19: 87.359376 | AA19: 89.495764 | AB19: 92.896241 | AC19: 92.814353 | AD19: =AVERAGE(T19:AC19) -> 91.623032 | AE19: =MAX(AD19-$C$3, 0) -> 0
A20: Req. N(0, 1) | B20: =_xlfn.NORM.INV((1+B19)/2, 0, 1) -> 1.959964 | F20: 18 | G20: =INDEX(Random!$F$2:$F$10001, ($F20-1)*10+G$2) -> -0.92534877 | H20: =INDEX(Random!$F$2:$F$10001, ($F20-1)*10+H$2) -> 1.2915863 | I20: =INDEX(Random!$F$2:$F$10001, ($F20-1)*10+I$2) -> -0.35022317 | J20: =INDEX(Random!$F$2:$F$10001, ($F20-1)*10+J$2) -> 0.013515742 | K20: =INDEX(Random!$F$2:$F$10001, ($F20-1)*10+K$2) -> 0.73665841 | L20: =INDEX(Random!$F$2:$F$10001, ($F20-1)*10+L$2) -> 0.16938929 | M20: =INDEX(Random!$F$2:$F$10001, ($F20-1)*10+M$2) -> 1.6989325 | N20: =INDEX(Random!$F$2:$F$10001, ($F20-1)*10+N$2) -> 1.4736148 | ... P20: =INDEX(Random!$F$2:$F$10001, ($F20-1)*10+P$2) -> 0.52453925 | R20: 18 | S20: 100 | T20: 96.986379 | U20: 101.32459 | V20: 100.18513 | W20: 100.27442 | X20: 102.82787 | Y20: 103.459 | Z20: 109.57364 | AA20: 115.17594 | AB20: 120.34294 | AC20: 122.53253 | AD20: =AVERAGE(T20:AC20) -> 107.26825 | AE20: =MAX(AD20-$C$3, 0) -> 6.268246
A21: Req. Simulations | B21: =(2*B10*B20*SQRT(COUNT(AE3:AE1002))/B18)^2 -> 9379086.3 | F21: 19 | G21: =INDEX(Random!$F$2:$F$10001, ($F21-1)*10+G$2) -> -1.9044745 | H21: =INDEX(Random!$F$2:$F$10001, ($F21-1)*10+H$2) -> -1.515581 | I21: =INDEX(Random!$F$2:$F$10001, ($F21-1)*10+I$2) -> 0.18264643 | J21: =INDEX(Random!$F$2:$F$10001, ($F21-1)*10+J$2) -> -0.44954431 | K21: =INDEX(Random!$F$2:$F$10001, ($F21-1)*10+K$2) -> -0.19142711 | L21: =INDEX(Random!$F$2:$F$10001, ($F21-1)*10+L$2) -> 0.033502695 | M21: =INDEX(Random!$F$2:$F$10001, ($F21-1)*10+M$2) -> 0.13121054 | N21: =INDEX(Random!$F$2:$F$10001, ($F21-1)*10+N$2) -> -1.8157033 | ... P21: =INDEX(Random!$F$2:$F$10001, ($F21-1)*10+P$2) -> 3.0040195 | R21: 19 | S21: 100 | T21: 93.852994 | U21: 89.240327 | V21: 89.827996 | W21: 88.522434 | X21: 87.994371 | Y21: 88.131857 | Z21: 88.55931 | AA21: 83.363408 | AB21: 82.60232 | AC21: 91.398872 | AD21: =AVERAGE(T21:AC21) -> 88.349389 | AE21: =MAX(AD21-$C$3, 0) -> 0
F22: 20 | G22: =INDEX(Random!$F$2:$F$10001, ($F22-1)*10+G$2) -> 0.50657076 | H22: =INDEX(Random!$F$2:$F$10001, ($F22-1)*10+H$2) -> -1.4943402 | I22: =INDEX(Random!$F$2:$F$10001, ($F22-1)*10+I$2) -> -0.29093213 | J22: =INDEX(Random!$F$2:$F$10001, ($F22-1)*10+J$2) -> 1.7727671 | K22: =INDEX(Random!$F$2:$F$10001, ($F22-1)*10+K$2) -> -0.67303217 | L22: =INDEX(Random!$F$2:$F$10001, ($F22-1)*10+L$2) -> -1.178126 | M22: =INDEX(Random!$F$2:$F$10001, ($F22-1)*10+M$2) -> -0.63206489 | N22: =INDEX(Random!$F$2:$F$10001, ($F22-1)*10+N$2) -> 0.59049889 | ... P22: =INDEX(Random!$F$2:$F$10001, ($F22-1)*10+P$2) -> 1.851038 | R22: 20 | S22: 100 | T22: 101.75812 | U22: 96.825888 | V22: 95.927599 | W22: 101.84903 | X22: 99.619205 | Y22: 95.801363 | Z22: 93.832785 | AA22: 95.75164 | AB22: 93.820904 | AC22: 99.87415 | AD22: =AVERAGE(T22:AC22) -> 97.506068 | AE22: =MAX(AD22-$C$3, 0) -> 0
B23: Seed Variance | F23: 21 | G23: =INDEX(Random!$F$2:$F$10001, ($F23-1)*10+G$2) -> -0.33808184 | H23: =INDEX(Random!$F$2:$F$10001, ($F23-1)*10+H$2) -> 1.1248831 | I23: =INDEX(Random!$F$2:$F$10001, ($F23-1)*10+I$2) -> -0.36602298 | J23: =INDEX(Random!$F$2:$F$10001, ($F23-1)*10+J$2) -> -1.0607678 | K23: =INDEX(Random!$F$2:$F$10001, ($F23-1)*10+K$2) -> -0.76456099 | L23: =INDEX(Random!$F$2:$F$10001, ($F23-1)*10+L$2) -> -1.9376445 | M23: =INDEX(Random!$F$2:$F$10001, ($F23-1)*10+M$2) -> -1.1027921 | N23: =INDEX(Random!$F$2:$F$10001, ($F23-1)*10+N$2) -> -0.2011474 | ... P23: =INDEX(Random!$F$2:$F$10001, ($F23-1)*10+P$2) -> -0.7853975 | R23: 21 | S23: 100 | T23: 98.91571 | U23: 102.76402 | V23: 101.55454 | W23: 98.047718 | X23: 95.607152 | Y23: 89.630401 | Z23: 86.413446 | AA23: 85.869963 | AB23: 89.6586 | AC23: 87.365773 | AD23: =AVERAGE(T23:AC23) -> 93.582733 | AE23: =MAX(AD23-$C$3, 0) -> 0
B24: Seed | C24: Result | F24: 22 | G24: =INDEX(Random!$F$2:$F$10001, ($F24-1)*10+G$2) -> 1.0760634 | H24: =INDEX(Random!$F$2:$F$10001, ($F24-1)*10+H$2) -> -0.74071011 | I24: =INDEX(Random!$F$2:$F$10001, ($F24-1)*10+I$2) -> -1.7706931 | J24: =INDEX(Random!$F$2:$F$10001, ($F24-1)*10+J$2) -> -1.5311485 | K24: =INDEX(Random!$F$2:$F$10001, ($F24-1)*10+K$2) -> 0.31007444 | L24: =INDEX(Random!$F$2:$F$10001, ($F24-1)*10+L$2) -> -0.2811732 | M24: =INDEX(Random!$F$2:$F$10001, ($F24-1)*10+M$2) -> -0.36223891 | N24: =INDEX(Random!$F$2:$F$10001, ($F24-1)*10+N$2) -> -0.40938281 | ... P24: =INDEX(Random!$F$2:$F$10001, ($F24-1)*10+P$2) -> -0.38245314 | R24: 22 | S24: 100 | T24: 103.72052 | U24: 101.21969 | V24: 95.424936 | W24: 90.687646 | X24: 91.675838 | Y24: 90.855063 | Z24: 89.797143 | AA24: 88.611314 | AB24: 89.85264 | AC24: 88.746202 | AD24: =AVERAGE(T24:AC24) -> 93.059099 | AE24: =MAX(AD24-$C$3, 0) -> 0
B25: 1 | C25: 2.4705985 | F25: 23 | G25: =INDEX(Random!$F$2:$F$10001, ($F25-1)*10+G$2) -> -1.059703 | H25: =INDEX(Random!$F$2:$F$10001, ($F25-1)*10+H$2) -> 1.3449595 | I25: =INDEX(Random!$F$2:$F$10001, ($F25-1)*10+I$2) -> -0.063395776 | J25: =INDEX(Random!$F$2:$F$10001, ($F25-1)*10+J$2) -> -0.042473125 | K25: =INDEX(Random!$F$2:$F$10001, ($F25-1)*10+K$2) -> 0.93970064 | L25: =INDEX(Random!$F$2:$F$10001, ($F25-1)*10+L$2) -> -1.9783065 | M25: =INDEX(Random!$F$2:$F$10001, ($F25-1)*10+M$2) -> 1.6353396 | N25: =INDEX(Random!$F$2:$F$10001, ($F25-1)*10+N$2) -> 0.56140283 | ... P25: =INDEX(Random!$F$2:$F$10001, ($F25-1)*10+P$2) -> 1.4743715 | R25: 23 | S25: 100 | T25: 96.550305 | U25: 101.04975 | V25: 100.87924 | W25: 100.77971 | X25: 104.05224 | Y25: 97.414603 | Z25: 102.95218 | AA25: 104.95504 | AB25: 105.90852 | AC25: 111.32625 | AD25: =AVERAGE(T25:AC25) -> 102.58678 | AE25: =MAX(AD25-$C$3, 0) -> 1.586783
B26: 2 | C26: 2.3292679 | F26: 24 | G26: =INDEX(Random!$F$2:$F$10001, ($F26-1)*10+G$2) -> 0.91574366 | H26: =INDEX(Random!$F$2:$F$10001, ($F26-1)*10+H$2) -> -2.1906269 | I26: =INDEX(Random!$F$2:$F$10001, ($F26-1)*10+I$2) -> -0.38515053 | J26: =INDEX(Random!$F$2:$F$10001, ($F26-1)*10+J$2) -> 1.2180627 | K26: =INDEX(Random!$F$2:$F$10001, ($F26-1)*10+K$2) -> 1.6744965 | L26: =INDEX(Random!$F$2:$F$10001, ($F26-1)*10+L$2) -> -0.0875683 | M26: =INDEX(Random!$F$2:$F$10001, ($F26-1)*10+M$2) -> -0.46789168 | N26: =INDEX(Random!$F$2:$F$10001, ($F26-1)*10+N$2) -> -0.2779581 | ... P26: =INDEX(Random!$F$2:$F$10001, ($F26-1)*10+P$2) -> 1.6012667 | R26: 24 | S26: 100 | T26: 103.16428 | U26: 95.897921 | V26: 94.708472 | W26: 98.701093 | X26: 104.44889 | Y26: 104.18813 | Z26: 102.61069 | AA26: 101.70298 | AB26: 106.2198 | AC26: 112.12969 | AD26: =AVERAGE(T26:AC26) -> 102.3772 | AE26: =MAX(AD26-$C$3, 0) -> 1.3771962
B27: 3 | C27: 2.4147829 | F27: 25 | G27: =INDEX(Random!$F$2:$F$10001, ($F27-1)*10+G$2) -> 0.14780736 | H27: =INDEX(Random!$F$2:$F$10001, ($F27-1)*10+H$2) -> 0.11756704 | I27: =INDEX(Random!$F$2:$F$10001, ($F27-1)*10+I$2) -> -0.45645903 | J27: =INDEX(Random!$F$2:$F$10001, ($F27-1)*10+J$2) -> -0.67331445 | K27: =INDEX(Random!$F$2:$F$10001, ($F27-1)*10+K$2) -> 0.79126275 | L27: =INDEX(Random!$F$2:$F$10001, ($F27-1)*10+L$2) -> 1.421711 | M27: =INDEX(Random!$F$2:$F$10001, ($F27-1)*10+M$2) -> -0.41542861 | N27: =INDEX(Random!$F$2:$F$10001, ($F27-1)*10+N$2) -> 0.58783493 | ... P27: =INDEX(Random!$F$2:$F$10001, ($F27-1)*10+P$2) -> 2.3245838 | R27: 25 | S27: 100 | T27: 100.54097 | U27: 100.98239 | V27: 99.491629 | W27: 97.312491 | X27: 99.973447 | Y27: 104.90212 | Z27: 103.49583 | AA27: 105.60286 | AB27: 101.89895 | AC27: 110.21004 | AD27: =AVERAGE(T27:AC27) -> 102.44107 | AE27: =MAX(AD27-$C$3, 0) -> 1.4410726
B28: 4 | C28: 2.4143405 | F28: 26 | G28: =INDEX(Random!$F$2:$F$10001, ($F28-1)*10+G$2) -> -2.1492981 | H28: =INDEX(Random!$F$2:$F$10001, ($F28-1)*10+H$2) -> 1.5711247 | I28: =INDEX(Random!$F$2:$F$10001, ($F28-1)*10+I$2) -> 0.18348877 | J28: =INDEX(Random!$F$2:$F$10001, ($F28-1)*10+J$2) -> -0.5884975 | K28: =INDEX(Random!$F$2:$F$10001, ($F28-1)*10+K$2) -> -1.1416854 | L28: =INDEX(Random!$F$2:$F$10001, ($F28-1)*10+L$2) -> -0.26244375 | M28: =INDEX(Random!$F$2:$F$10001, ($F28-1)*10+M$2) -> 1.6749552 | N28: =INDEX(Random!$F$2:$F$10001, ($F28-1)*10+N$2) -> 0.35415635 | ... P28: =INDEX(Random!$F$2:$F$10001, ($F28-1)*10+P$2) -> -0.96541947 | R28: 26 | S28: 100 | T28: 93.085464 | U28: 98.165287 | V28: 98.81452 | W28: 96.925559 | X28: 93.324948 | Y28: 92.547528 | Z28: 97.938481 | AA28: 99.152176 | AB28: 100.78547 | AC28: 97.616895 | AD28: =AVERAGE(T28:AC28) -> 96.835633 | AE28: =MAX(AD28-$C$3, 0) -> 0
B29: 5 | C29: 2.6093686 | F29: 27 | G29: =INDEX(Random!$F$2:$F$10001, ($F29-1)*10+G$2) -> -0.42205977 | H29: =INDEX(Random!$F$2:$F$10001, ($F29-1)*10+H$2) -> 0.65071882 | I29: =INDEX(Random!$F$2:$F$10001, ($F29-1)*10+I$2) -> 0.56611331 | J29: =INDEX(Random!$F$2:$F$10001, ($F29-1)*10+J$2) -> 2.1533465 | K29: =INDEX(Random!$F$2:$F$10001, ($F29-1)*10+K$2) -> 0.7226151 | L29: =INDEX(Random!$F$2:$F$10001, ($F29-1)*10+L$2) -> -0.43169873 | M29: =INDEX(Random!$F$2:$F$10001, ($F29-1)*10+M$2) -> -0.56222676 | N29: =INDEX(Random!$F$2:$F$10001, ($F29-1)*10+N$2) -> 1.0302593 | ... P29: =INDEX(Random!$F$2:$F$10001, ($F29-1)*10+P$2) -> 0.25246204 | R29: 27 | S29: 100 | T29: 98.637486 | U29: 100.85811 | V29: 102.83648 | W29: 110.58706 | X29: 113.34971 | Y29: 111.76917 | Z29: 109.72921 | AA29: 113.63698 | AB29: 115.05289 | AC29: 116.08205 | AD29: =AVERAGE(T29:AC29) -> 109.25391 | AE29: =MAX(AD29-$C$3, 0) -> 8.253914
B30: 6 | C30: 2.2850305 | F30: 28 | G30: =INDEX(Random!$F$2:$F$10001, ($F30-1)*10+G$2) -> -1.3255674 | H30: =INDEX(Random!$F$2:$F$10001, ($F30-1)*10+H$2) -> 0.40636932 | I30: =INDEX(Random!$F$2:$F$10001, ($F30-1)*10+I$2) -> 1.5889861 | J30: =INDEX(Random!$F$2:$F$10001, ($F30-1)*10+J$2) -> -0.55122348 | K30: =INDEX(Random!$F$2:$F$10001, ($F30-1)*10+K$2) -> -0.46125857 | L30: =INDEX(Random!$F$2:$F$10001, ($F30-1)*10+L$2) -> -1.5581412 | M30: =INDEX(Random!$F$2:$F$10001, ($F30-1)*10+M$2) -> 1.6111084 | N30: =INDEX(Random!$F$2:$F$10001, ($F30-1)*10+N$2) -> 0.6256355 | ... P30: =INDEX(Random!$F$2:$F$10001, ($F30-1)*10+P$2) -> 0.18288603 | R30: 28 | S30: 100 | T30: 95.693158 | U30: 97.048839 | V30: 102.40628 | W30: 100.57432 | X30: 99.073637 | Y30: 94.070005 | Z30: 99.336687 | AA30: 101.48763 | AB30: 103.1112 | AC30: 103.79104 | AD30: =AVERAGE(T30:AC30) -> 99.659279 | AE30: =MAX(AD30-$C$3, 0) -> 0
B31: 7 | C31: 2.4043669 | F31: 29 | G31: =INDEX(Random!$F$2:$F$10001, ($F31-1)*10+G$2) -> 1.0992154 | H31: =INDEX(Random!$F$2:$F$10001, ($F31-1)*10+H$2) -> -2.3402067 | I31: =INDEX(Random!$F$2:$F$10001, ($F31-1)*10+I$2) -> -0.97350506 | J31: =INDEX(Random!$F$2:$F$10001, ($F31-1)*10+J$2) -> -2.2473107 | K31: =INDEX(Random!$F$2:$F$10001, ($F31-1)*10+K$2) -> -0.77144961 | L31: =INDEX(Random!$F$2:$F$10001, ($F31-1)*10+L$2) -> -0.67078281 | M31: =INDEX(Random!$F$2:$F$10001, ($F31-1)*10+M$2) -> 0.47685784 | N31: =INDEX(Random!$F$2:$F$10001, ($F31-1)*10+N$2) -> -1.6943053 | ... P31: =INDEX(Random!$F$2:$F$10001, ($F31-1)*10+P$2) -> 2.2461962 | R31: 29 | S31: 100 | T31: 103.80109 | U31: 96.006997 | V31: 92.963433 | W31: 86.251429 | X31: 84.085061 | Y31: 82.250353 | Z31: 83.613039 | AA31: 79.028477 | AB31: 76.844577 | AC31: 82.893952 | AD31: =AVERAGE(T31:AC31) -> 86.773841 | AE31: =MAX(AD31-$C$3, 0) -> 0
B32: 8 | C32: 2.3797098 | F32: 30 | G32: =INDEX(Random!$F$2:$F$10001, ($F32-1)*10+G$2) -> -1.5574808 | H32: =INDEX(Random!$F$2:$F$10001, ($F32-1)*10+H$2) -> 0.59980618 | I32: =INDEX(Random!$F$2:$F$10001, ($F32-1)*10+I$2) -> -0.22764178 | J32: =INDEX(Random!$F$2:$F$10001, ($F32-1)*10+J$2) -> -0.543103 | K32: =INDEX(Random!$F$2:$F$10001, ($F32-1)*10+K$2) -> 1.7482948 | L32: =INDEX(Random!$F$2:$F$10001, ($F32-1)*10+L$2) -> -0.86964766 | M32: =INDEX(Random!$F$2:$F$10001, ($F32-1)*10+M$2) -> 1.4784269 | N32: =INDEX(Random!$F$2:$F$10001, ($F32-1)*10+N$2) -> -1.4022514 | ... P32: =INDEX(Random!$F$2:$F$10001, ($F32-1)*10+P$2) -> -0.99598083 | R32: 30 | S32: 100 | T32: 94.951686 | U32: 96.923674 | V32: 96.228538 | W32: 94.532835 | X32: 100.28582 | Y32: 97.445472 | Z32: 102.44421 | AA32: 97.780284 | AB32: 103.68478 | AC32: 100.32216 | AD32: =AVERAGE(T32:AC32) -> 98.459946 | AE32: =MAX(AD32-$C$3, 0) -> 0
B33: 9 | C33: 2.3077982 | F33: 31 | G33: =INDEX(Random!$F$2:$F$10001, ($F33-1)*10+G$2) -> -0.033394567 | H33: =INDEX(Random!$F$2:$F$10001, ($F33-1)*10+H$2) -> 0.072452585 | I33: =INDEX(Random!$F$2:$F$10001, ($F33-1)*10+I$2) -> 0.061529165 | J33: =INDEX(Random!$F$2:$F$10001, ($F33-1)*10+J$2) -> 0.36115172 | K33: =INDEX(Random!$F$2:$F$10001, ($F33-1)*10+K$2) -> -1.6625861 | L33: =INDEX(Random!$F$2:$F$10001, ($F33-1)*10+L$2) -> 0.12309347 | M33: =INDEX(Random!$F$2:$F$10001, ($F33-1)*10+M$2) -> 2.0663362 | N33: =INDEX(Random!$F$2:$F$10001, ($F33-1)*10+N$2) -> 0.30857423 | ... P33: =INDEX(Random!$F$2:$F$10001, ($F33-1)*10+P$2) -> -0.27657698 | R33: 31 | S33: 100 | T33: 99.931765 | U33: 100.21874 | V33: 100.46973 | W33: 101.73866 | X33: 96.262617 | Y33: 96.703174 | Z33: 103.68845 | AA33: 104.81304 | AB33: 108.54855 | AC33: 107.5933 | AD33: =AVERAGE(T33:AC33) -> 101.9968 | AE33: =MAX(AD33-$C$3, 0) -> 0.99680204
B34: 10 | C34: 2.6695951 | F34: 32 | G34: =INDEX(Random!$F$2:$F$10001, ($F34-1)*10+G$2) -> -0.015224002 | H34: =INDEX(Random!$F$2:$F$10001, ($F34-1)*10+H$2) -> -0.41933002 | I34: =INDEX(Random!$F$2:$F$10001, ($F34-1)*10+I$2) -> 1.0720949 | J34: =INDEX(Random!$F$2:$F$10001, ($F34-1)*10+J$2) -> -0.51217494 | K34: =INDEX(Random!$F$2:$F$10001, ($F34-1)*10+K$2) -> -1.0734286 | L34: =INDEX(Random!$F$2:$F$10001, ($F34-1)*10+L$2) -> -0.67669072 | M34: =INDEX(Random!$F$2:$F$10001, ($F34-1)*10+M$2) -> -2.2089012 | N34: =INDEX(Random!$F$2:$F$10001, ($F34-1)*10+N$2) -> -1.7579616 | ... P34: =INDEX(Random!$F$2:$F$10001, ($F34-1)*10+P$2) -> 0.35498975 | R34: 32 | S34: 100 | T34: 99.992687 | U34: 98.639304 | V34: 102.29558 | W34: 100.59727 | X34: 97.082264 | Y34: 94.945145 | Z34: 88.20362 | AA34: 83.189545 | AB34: 85.298215 | AC34: 86.35768 | AD34: =AVERAGE(T34:AC34) -> 93.660131 | AE34: =MAX(AD34-$C$3, 0) -> 0
B35: 11 | C35: 2.5300193 | F35: 33 | G35: =INDEX(Random!$F$2:$F$10001, ($F35-1)*10+G$2) -> 0.68549851 | H35: =INDEX(Random!$F$2:$F$10001, ($F35-1)*10+H$2) -> -0.027673835 | I35: =INDEX(Random!$F$2:$F$10001, ($F35-1)*10+I$2) -> 0.36776929 | J35: =INDEX(Random!$F$2:$F$10001, ($F35-1)*10+J$2) -> -0.53611095 | K35: =INDEX(Random!$F$2:$F$10001, ($F35-1)*10+K$2) -> -0.34512692 | L35: =INDEX(Random!$F$2:$F$10001, ($F35-1)*10+L$2) -> 1.2253392 | M35: =INDEX(Random!$F$2:$F$10001, ($F35-1)*10+M$2) -> -0.2782453 | N35: =INDEX(Random!$F$2:$F$10001, ($F35-1)*10+N$2) -> 0.19976338 | ... P35: =INDEX(Random!$F$2:$F$10001, ($F35-1)*10+P$2) -> 0.7344714 | R35: 33 | S35: 100 | T35: 102.37065 | U35: 102.32042 | V35: 103.63573 | W35: 101.83338 | X35: 100.70541 | Y35: 104.97646 | Z35: 104.04682 | AA35: 104.79214 | AB35: 112.23419 | AC35: 115.08375 | AD35: =AVERAGE(T35:AC35) -> 105.1999 | AE35: =MAX(AD35-$C$3, 0) -> 4.1998962
B36: 12 | C36: 2.4059226 | F36: 34 | G36: =INDEX(Random!$F$2:$F$10001, ($F36-1)*10+G$2) -> -0.16702778 | H36: =INDEX(Random!$F$2:$F$10001, ($F36-1)*10+H$2) -> 1.1865835 | I36: =INDEX(Random!$F$2:$F$10001, ($F36-1)*10+I$2) -> 0.51836205 | J36: =INDEX(Random!$F$2:$F$10001, ($F36-1)*10+J$2) -> -0.8649544 | K36: =INDEX(Random!$F$2:$F$10001, ($F36-1)*10+K$2) -> 2.0292769 | L36: =INDEX(Random!$F$2:$F$10001, ($F36-1)*10+L$2) -> 1.4648753 | M36: =INDEX(Random!$F$2:$F$10001, ($F36-1)*10+M$2) -> 0.55525535 | N36: =INDEX(Random!$F$2:$F$10001, ($F36-1)*10+N$2) -> -0.51568404 | ... P36: =INDEX(Random!$F$2:$F$10001, ($F36-1)*10+P$2) -> -2.0460679 | R36: 34 | S36: 100 | T36: 99.484853 | U36: 103.56942 | V36: 105.43198 | W36: 102.46201 | X36: 109.72679 | Y36: 115.30312 | Z36: 117.52203 | AA36: 115.55733 | AB36: 121.34792 | AC36: 113.34906 | AD36: =AVERAGE(T36:AC36) -> 110.37545 | AE36: =MAX(AD36-$C$3, 0) -> 9.3754509
... B44: 20 | C44: 2.5166511 | F44: 42 | G44: =INDEX(Random!$F$2:$F$10001, ($F44-1)*10+G$2) -> 1.4018003 | H44: =INDEX(Random!$F$2:$F$10001, ($F44-1)*10+H$2) -> 0.80931483 | I44: =INDEX(Random!$F$2:$F$10001, ($F44-1)*10+I$2) -> -0.53045102 | J44: =INDEX(Random!$F$2:$F$10001, ($F44-1)*10+J$2) -> 1.3598739 | K44: =INDEX(Random!$F$2:$F$10001, ($F44-1)*10+K$2) -> 0.16198968 | L44: =INDEX(Random!$F$2:$F$10001, ($F44-1)*10+L$2) -> -0.24970672 | M44: =INDEX(Random!$F$2:$F$10001, ($F44-1)*10+M$2) -> -0.46465513 | N44: =INDEX(Random!$F$2:$F$10001, ($F44-1)*10+N$2) -> -0.53053799 | ... P44: =INDEX(Random!$F$2:$F$10001, ($F44-1)*10+P$2) -> -0.99934993 | R44: 42 | S44: 100 | T44: 104.85993 | U44: 107.79252 | V44: 105.93798 | W44: 110.93039 | X44: 111.58356 | Y44: 110.70133 | Z44: 109.03711 | AA44: 107.16085 | AB44: 106.82916 | AC44: 103.35288 | AD44: =AVERAGE(T44:AC44) -> 107.81857 | AE44: =MAX(AD44-$C$3, 0) -> 6.8185725
F45: 43 | G45: =INDEX(Random!$F$2:$F$10001, ($F45-1)*10+G$2) -> -1.7146243 | H45: =INDEX(Random!$F$2:$F$10001, ($F45-1)*10+H$2) -> 0.38070874 | I45: =INDEX(Random!$F$2:$F$10001, ($F45-1)*10+I$2) -> 0.30919629 | J45: =INDEX(Random!$F$2:$F$10001, ($F45-1)*10+J$2) -> -0.61280931 | K45: =INDEX(Random!$F$2:$F$10001, ($F45-1)*10+K$2) -> -0.74284828 | L45: =INDEX(Random!$F$2:$F$10001, ($F45-1)*10+L$2) -> 0.72643709 | M45: =INDEX(Random!$F$2:$F$10001, ($F45-1)*10+M$2) -> 1.5846953 | N45: =INDEX(Random!$F$2:$F$10001, ($F45-1)*10+N$2) -> 0.95372689 | ... P45: =INDEX(Random!$F$2:$F$10001, ($F45-1)*10+P$2) -> 0.018944112 | R45: 43 | S45: 100 | T45: 94.452536 | U45: 95.708231 | V45: 96.74828 | W45: 94.821465 | X45: 92.528566 | Y45: 94.852245 | Z45: 100.07402 | AA45: 103.37226 | AB45: 104.06869 | AC45: 104.18041 | AD45: =AVERAGE(T45:AC45) -> 98.080671 | AE45: =MAX(AD45-$C$3, 0) -> 0
B46: Mean | C46: =AVERAGE(C25:C44) -> 2.4047472 | F46: 44 | G46: =INDEX(Random!$F$2:$F$10001, ($F46-1)*10+G$2) -> -0.54923322 | H46: =INDEX(Random!$F$2:$F$10001, ($F46-1)*10+H$2) -> -0.62703633 | I46: =INDEX(Random!$F$2:$F$10001, ($F46-1)*10+I$2) -> -1.0316265 | J46: =INDEX(Random!$F$2:$F$10001, ($F46-1)*10+J$2) -> 1.2031952 | K46: =INDEX(Random!$F$2:$F$10001, ($F46-1)*10+K$2) -> -0.34465332 | L46: =INDEX(Random!$F$2:$F$10001, ($F46-1)*10+L$2) -> -0.041663635 | M46: =INDEX(Random!$F$2:$F$10001, ($F46-1)*10+M$2) -> -0.25039376 | N46: =INDEX(Random!$F$2:$F$10001, ($F46-1)*10+N$2) -> -0.0056051053 | ... P46: =INDEX(Random!$F$2:$F$10001, ($F46-1)*10+P$2) -> 0.90382666 | R46: 44 | S46: 100 | T46: 98.217641 | U46: 96.215638 | V46: 92.984015 | W46: 96.855628 | X46: 95.784318 | Y46: 95.692414 | Z46: 94.933635 | AA46: 94.957324 | AB46: 95.490234 | AC46: 98.472444 | AD46: =AVERAGE(T46:AC46) -> 95.960329 | AE46: =MAX(AD46-$C$3, 0) -> 0
B47: Std Dev | C47: =_xlfn.STDEV.S(C25:C44) -> 0.13306464 | F47: 45 | G47: =INDEX(Random!$F$2:$F$10001, ($F47-1)*10+G$2) -> -0.52609731 | H47: =INDEX(Random!$F$2:$F$10001, ($F47-1)*10+H$2) -> 0.97237896 | I47: =INDEX(Random!$F$2:$F$10001, ($F47-1)*10+I$2) -> -0.053140408 | J47: =INDEX(Random!$F$2:$F$10001, ($F47-1)*10+J$2) -> 0.35408848 | K47: =INDEX(Random!$F$2:$F$10001, ($F47-1)*10+K$2) -> -0.11387998 | L47: =INDEX(Random!$F$2:$F$10001, ($F47-1)*10+L$2) -> -0.82392934 | M47: =INDEX(Random!$F$2:$F$10001, ($F47-1)*10+M$2) -> -1.5117095 | N47: =INDEX(Random!$F$2:$F$10001, ($F47-1)*10+N$2) -> -0.57070503 | ... P47: =INDEX(Random!$F$2:$F$10001, ($F47-1)*10+P$2) -> -0.62143795 | R47: 45 | S47: 100 | T47: 98.293888 | U47: 101.59699 | V47: 101.46045 | W47: 102.71755 | X47: 102.37074 | Y47: 99.623985 | Z47: 94.739988 | AA47: 92.984391 | AB47: 95.48363 | AC47: 93.554921 | AD47: =AVERAGE(T47:AC47) -> 98.282653 | AE47: =MAX(AD47-$C$3, 0) -> 0
...

Sheet Rainbow Call
A1: Option Parameters | H1: Uncorrelated N(0, 1) | M1: Correlated N(0, 1) | Q1: New spot rate | U1: Spot Rate Growth | Y1: Payoff
A2: Strike | B2: K | C2: 1 | E2: Call Price | F2: =AVERAGE(Y3:Y5002) * EXP(-$F$11*$C$3) -> 31.558743 | H2: Trial | I2: 1 | J2: 2 | K2: 3 | L2: 4 | M2: 1 | N2: 2 | O2: 3 | P2: 4 | Q2: =B20 -> EUR | R2: =C20 -> GBP | S2: =D20 -> JPY | T2: =E20 -> CAD | U2: =B20 -> EUR | V2: =C20 -> GBP | W2: =D20 -> JPY | X2: =E20 -> CAD
A3: Maturity | B3: T | C3: 0.25 | H3: 1 | I3: =INDEX(Random!$F$2:$F$10003,($H3-1)*$L$2 + I$2) -> 0.77003388 | J3: =INDEX(Random!$F$2:$F$10003,($H3-1)*$L$2 + J$2) -> -0.021471217 | K3: =INDEX(Random!$F$2:$F$10003,($H3-1)*$L$2 + K$2) -> -1.6148261 | L3: =INDEX(Random!$F$2:$F$10003,($H3-1)*$L$2 + L$2) -> 0.74132908 | M3: {=TRANSPOSE(MMULT($B$28:$E$31, TRANSPOSE(I3:L3)))} -> 0.77003388 | N3: 0.59174475 | O3: -0.90230544 | P3: 1.0301264 | Q3: =$B$7 * EXP(($F$11 - $F$7 - $C$7*$C$7/2)*$C$3 + M3*$C$7*SQRT($C$3)) -> 1.2086791 | R3: =$B$8 * EXP(($F$11 - $F$8 - $C$8*$C$8/2)*$C$3 + N3*$C$8*SQRT($C$3)) -> 1.3791948 | S3: =$B$9 * EXP(($F$11 - $F$9 - $C$9*$C$9/2)*$C$3 + O3*$C$9*SQRT($C$3)) -> 0.0060673933 | T3: =$B$10 * EXP(($F$11 - $F$10 - $C$10*$C$10/2)*$C$3 + P3*$C$10*SQRT($C$3)) -> 0.7444139 | U3: =Q3/$B$7 -> 1.028663 | V3: =R3/$B$8 -> 1.0208696 | W3: =S3/$B$9 -> 0.96923216 | X3: =T3/$B$10 -> 1.0296181 | Y3: =$C$4 * (MAX(MAX(U3:X3) - $C$2, 0)) -> 29.618114
A4: Notional | B4: N | C4: 1000 | H4: 2 | I4: =INDEX(Random!$F$2:$F$10003,($H4-1)*$L$2 + I$2) -> -2.0600803 | J4: =INDEX(Random!$F$2:$F$10003,($H4-1)*$L$2 + J$2) -> 0.57768722 | K4: =INDEX(Random!$F$2:$F$10003,($H4-1)*$L$2 + K$2) -> -0.70092551 | L4: =INDEX(Random!$F$2:$F$10003,($H4-1)*$L$2 + L$2) -> 1.1843771 | M4: {=TRANSPOSE(MMULT($B$28:$E$31, TRANSPOSE(I4:L4)))} -> -2.0600803 | N4: -1.2612832 | O4: -1.7002561 | P4: -0.01955858 | Q4: =$B$7 * EXP(($F$11 - $F$7 - $C$7*$C$7/2)*$C$3 + M4*$C$7*SQRT($C$3)) -> 1.1055904 | R4: =$B$8 * EXP(($F$11 - $F$8 - $C$8*$C$8/2)*$C$3 + N4*$C$8*SQRT($C$3)) -> 1.2901918 | S4: =$B$9 * EXP(($F$11 - $F$9 - $C$9*$C$9/2)*$C$3 + O4*$C$9*SQRT($C$3)) -> 0.0058650803 | T4: =$B$10 * EXP(($F$11 - $F$10 - $C$10*$C$10/2)*$C$3 + P4*$C$10*SQRT($C$3)) -> 0.72551367 | U4: =Q4/$B$7 -> 0.940928 | V4: =R4/$B$8 -> 0.9549902 | W4: =S4/$B$9 -> 0.93691379 | X4: =T4/$B$10 -> 1.0034767 | Y4: =$C$4 * (MAX(MAX(U4:X4) - $C$2, 0)) -> 3.4767196
H5: 3 | I5: =INDEX(Random!$F$2:$F$10003,($H5-1)*$L$2 + I$2) -> 0.39750655 | J5: =INDEX(Random!$F$2:$F$10003,($H5-1)*$L$2 + J$2) -> 0.038342654 | K5: =INDEX(Random!$F$2:$F$10003,($H5-1)*$L$2 + K$2) -> 0.51504409 | L5: =INDEX(Random!$F$2:$F$10003,($H5-1)*$L$2 + L$2) -> -0.57350867 | M5: {=TRANSPOSE(MMULT($B$28:$E$31, TRANSPOSE(I5:L5)))} -> 0.39750655 | N5: 0.33604494 | O5: 0.65054906 | P5: -0.24600698 | Q5: =$B$7 * EXP(($F$11 - $F$7 - $C$7*$C$7/2)*$C$3 + M5*$C$7*SQRT($C$3)) -> 1.1945786 | R5: =$B$8 * EXP(($F$11 - $F$8 - $C$8*$C$8/2)*$C$3 + N5*$C$8*SQRT($C$3)) -> 1.3665573 | S5: =$B$9 * EXP(($F$11 - $F$9 - $C$9*$C$9/2)*$C$3 + O5*$C$9*SQRT($C$3)) -> 0.0064813278 | T5: =$B$10 * EXP(($F$11 - $F$10 - $C$10*$C$10/2)*$C$3 + P5*$C$10*SQRT($C$3)) -> 0.72149967 | U5: =Q5/$B$7 -> 1.0166626 | V5: =R5/$B$8 -> 1.0115154 | W5: =S5/$B$9 -> 1.0353559 | X5: =T5/$B$10 -> 0.99792486 | Y5: =$C$4 * (MAX(MAX(U5:X5) - $C$2, 0)) -> 35.355877
A6: CcyPair | B6: Spot | C6: Vol | E6: Ccy | F6: Yield | H6: 4 | I6: =INDEX(Random!$F$2:$F$10003,($H6-1)*$L$2 + I$2) -> 1.5680918 | J6: =INDEX(Random!$F$2:$F$10003,($H6-1)*$L$2 + J$2) -> 0.081428152 | K6: =INDEX(Random!$F$2:$F$10003,($H6-1)*$L$2 + K$2) -> 1.0743323 | L6: =INDEX(Random!$F$2:$F$10003,($H6-1)*$L$2 + L$2) -> 0.069042537 | M6: {=TRANSPOSE(MMULT($B$28:$E$31, TRANSPOSE(I6:L6)))} -> 1.5680918 | N6: 1.2824427 | O6: 1.7717262 | P6: 0.91220415 | Q6: =$B$7 * EXP(($F$11 - $F$7 - $C$7*$C$7/2)*$C$3 + M6*$C$7*SQRT($C$3)) -> 1.239449 | R6: =$B$8 * EXP(($F$11 - $F$8 - $C$8*$C$8/2)*$C$3 + N6*$C$8*SQRT($C$3)) -> 1.4139186 | S6: =$B$9 * EXP(($F$11 - $F$9 - $C$9*$C$9/2)*$C$3 + O6*$C$9*SQRT($C$3)) -> 0.0067976395 | T6: =$B$10 * EXP(($F$11 - $F$10 - $C$10*$C$10/2)*$C$3 + P6*$C$10*SQRT($C$3)) -> 0.74226632 | U6: =Q6/$B$7 -> 1.0548502 | V6: =R6/$B$8 -> 1.0465719 | W6: =S6/$B$9 -> 1.0858849 | X6: =T6/$B$10 -> 1.0266477 | Y6: =$C$4 * (MAX(MAX(U6:X6) - $C$2, 0)) -> 85.884907
A7: EURUSD | B7: 1.175 | C7: 0.063 | E7: EUR | F7: 0.02 | H7: 5 | I7: =INDEX(Random!$F$2:$F$10003,($H7-1)*$L$2 + I$2) -> -2.04904 | J7: =INDEX(Random!$F$2:$F$10003,($H7-1)*$L$2 + J$2) -> -0.05263592 | K7: =INDEX(Random!$F$2:$F$10003,($H7-1)*$L$2 + K$2) -> -0.41277469 | L7: =INDEX(Random!$F$2:$F$10003,($H7-1)*$L$2 + L$2) -> 0.33127521 | M7: {=TRANSPOSE(MMULT($B$28:$E$31, TRANSPOSE(I7:L7)))} -> -2.04904 | N7: -1.64252 | O7: -1.4937423 | P7: -0.84925536 | Q7: =$B$7 * EXP(($F$11 - $F$7 - $C$7*$C$7/2)*$C$3 + M7*$C$7*SQRT($C$3)) -> 1.105975 | R7: =$B$8 * EXP(($F$11 - $F$8 - $C$8*$C$8/2)*$C$3 + N7*$C$8*SQRT($C$3)) -> 1.2726055 | S7: =$B$9 * EXP(($F$11 - $F$9 - $C$9*$C$9/2)*$C$3 + O7*$C$9*SQRT($C$3)) -> 0.0059167837 | T7: =$B$10 * EXP(($F$11 - $F$10 - $C$10*$C$10/2)*$C$3 + P7*$C$10*SQRT($C$3)) -> 0.71091462 | U7: =Q7/$B$7 -> 0.94125529 | V7: =R7/$B$8 -> 0.94197295 | W7: =S7/$B$9 -> 0.94517312 | X7: =T7/$B$10 -> 0.9832844 | Y7: =$C$4 * (MAX(MAX(U7:X7) - $C$2, 0)) -> 0
A8: GBPUSD | B8: 1.351 | C8: 0.072 | E8: GBP | F8: 0.038 | H8: 6 | I8: =INDEX(Random!$F$2:$F$10003,($H8-1)*$L$2 + I$2) -> -0.87000051 | J8: =INDEX(Random!$F$2:$F$10003,($H8-1)*$L$2 + J$2) -> -0.59562722 | K8: =INDEX(Random!$F$2:$F$10003,($H8-1)*$L$2 + K$2) -> 1.287163 | L8: =INDEX(Random!$F$2:$F$10003,($H8-1)*$L$2 + L$2) -> -0.62332952 | M8: {=TRANSPOSE(MMULT($B$28:$E$31, TRANSPOSE(I8:L8)))} -> -0.87000051 | N8: -1.0520206 | O8: 0.53892355 | P8: -1.1239364 | Q8: =$B$7 * EXP(($F$11 - $F$7 - $C$7*$C$7/2)*$C$3 + M8*$C$7*SQRT($C$3)) -> 1.1478229 | R8: =$B$8 * EXP(($F$11 - $F$8 - $C$8*$C$8/2)*$C$3 + N8*$C$8*SQRT($C$3)) -> 1.2999481 | S8: =$B$9 * EXP(($F$11 - $F$9 - $C$9*$C$9/2)*$C$3 + O8*$C$9*SQRT($C$3)) -> 0.0064506526 | T8: =$B$10 * EXP(($F$11 - $F$10 - $C$10*$C$10/2)*$C$3 + P8*$C$10*SQRT($C$3)) -> 0.70614645 | U8: =Q8/$B$7 -> 0.97687054 | V8: =R8/$B$8 -> 0.96221175 | W8: =S8/$B$9 -> 1.0304557 | X8: =T8/$B$10 -> 0.97668942 | Y8: =$C$4 * (MAX(MAX(U8:X8) - $C$2, 0)) -> 30.455694
A9: JPYUSD | B9: 0.00626 | C9: 0.085 | E9: JPY | F9: 0.006 | H9: 7 | I9: =INDEX(Random!$F$2:$F$10003,($H9-1)*$L$2 + I$2) -> 1.0930683 | J9: =INDEX(Random!$F$2:$F$10003,($H9-1)*$L$2 + J$2) -> -1.3301227 | K9: =INDEX(Random!$F$2:$F$10003,($H9-1)*$L$2 + K$2) -> -0.44077363 | L9: =INDEX(Random!$F$2:$F$10003,($H9-1)*$L$2 + L$2) -> -0.27732365 | M9: {=TRANSPOSE(MMULT($B$28:$E$31, TRANSPOSE(I9:L9)))} -> 1.0930683 | N9: 0.03603932 | O9: 0.17022296 | P9: 0.073334753 | Q9: =$B$7 * EXP(($F$11 - $F$7 - $C$7*$C$7/2)*$C$3 + M9*$C$7*SQRT($C$3)) -> 1.2210409 | R9: =$B$8 * EXP(($F$11 - $F$8 - $C$8*$C$8/2)*$C$3 + N9*$C$8*SQRT($C$3)) -> 1.3518776 | S9: =$B$9 * EXP(($F$11 - $F$9 - $C$9*$C$9/2)*$C$3 + O9*$C$9*SQRT($C$3)) -> 0.0063503602 | T9: =$B$10 * EXP(($F$11 - $F$10 - $C$10*$C$10/2)*$C$3 + P9*$C$10*SQRT($C$3)) -> 0.72716674 | U9: =Q9/$B$7 -> 1.0391837 | V9: =R9/$B$8 -> 1.0006496 | W9: =S9/$B$9 -> 1.0144345 | X9: =T9/$B$10 -> 1.0057631 | Y9: =$C$4 * (MAX(MAX(U9:X9) - $C$2, 0)) -> 39.183725
A10: CADUSD | B10: 0.723 | C10: 0.049 | E10: CAD | F10: 0.021 | H10: 8 | I10: =INDEX(Random!$F$2:$F$10003,($H10-1)*$L$2 + I$2) -> 0.40161095 | J10: =INDEX(Random!$F$2:$F$10003,($H10-1)*$L$2 + J$2) -> -0.022358811 | K10: =INDEX(Random!$F$2:$F$10003,($H10-1)*$L$2 + K$2) -> 1.8063811 | L10: =INDEX(Random!$F$2:$F$10003,($H10-1)*$L$2 + L$2) -> 0.79484663 | M10: {=TRANSPOSE(MMULT($B$28:$E$31, TRANSPOSE(I10:L10)))} -> 0.40161095 | N10: 0.30172053 | O10: 1.715311 | P10: 0.83675533 | Q10: =$B$7 * EXP(($F$11 - $F$7 - $C$7*$C$7/2)*$C$3 + M10*$C$7*SQRT($C$3)) -> 1.194733 | R10: =$B$8 * EXP(($F$11 - $F$8 - $C$8*$C$8/2)*$C$3 + N10*$C$8*SQRT($C$3)) -> 1.3648697 | S10: =$B$9 * EXP(($F$11 - $F$9 - $C$9*$C$9/2)*$C$3 + O10*$C$9*SQRT($C$3)) -> 0.0067813607 | T10: =$B$10 * EXP(($F$11 - $F$10 - $C$10*$C$10/2)*$C$3 + P10*$C$10*SQRT($C$3)) -> 0.74089551 | U10: =Q10/$B$7 -> 1.0167941 | V10: =R10/$B$8 -> 1.0102663 | W10: =S10/$B$9 -> 1.0832845 | X10: =T10/$B$10 -> 1.0247517 | Y10: =$C$4 * (MAX(MAX(U10:X10) - $C$2, 0)) -> 83.284458
E11: USD | F11: 0.038 | H11: 9 | I11: =INDEX(Random!$F$2:$F$10003,($H11-1)*$L$2 + I$2) -> -0.47784146 | J11: =INDEX(Random!$F$2:$F$10003,($H11-1)*$L$2 + J$2) -> -1.6202444 | K11: =INDEX(Random!$F$2:$F$10003,($H11-1)*$L$2 + K$2) -> 0.16814432 | L11: =INDEX(Random!$F$2:$F$10003,($H11-1)*$L$2 + L$2) -> -0.46930818 | M11: {=TRANSPOSE(MMULT($B$28:$E$31, TRANSPOSE(I11:L11)))} -> -0.47784146 | N11: -1.3777132 | O11: -0.22589813 | P11: -1.0050336 | Q11: =$B$7 * EXP(($F$11 - $F$7 - $C$7*$C$7/2)*$C$3 + M11*$C$7*SQRT($C$3)) -> 1.1620899 | R11: =$B$8 * EXP(($F$11 - $F$8 - $C$8*$C$8/2)*$C$3 + N11*$C$8*SQRT($C$3)) -> 1.2847953 | S11: =$B$9 * EXP(($F$11 - $F$9 - $C$9*$C$9/2)*$C$3 + O11*$C$9*SQRT($C$3)) -> 0.0062443458 | T11: =$B$10 * EXP(($F$11 - $F$10 - $C$10*$C$10/2)*$C$3 + P11*$C$10*SQRT($C$3)) -> 0.70820654 | U11: =Q11/$B$7 -> 0.98901268 | V11: =R11/$B$8 -> 0.95099576 | W11: =S11/$B$9 -> 0.99749934 | X11: =T11/$B$10 -> 0.97953878 | Y11: =$C$4 * (MAX(MAX(U11:X11) - $C$2, 0)) -> 0
H12: 10 | I12: =INDEX(Random!$F$2:$F$10003,($H12-1)*$L$2 + I$2) -> 1.6344115 | J12: =INDEX(Random!$F$2:$F$10003,($H12-1)*$L$2 + J$2) -> -2.1378119 | K12: =INDEX(Random!$F$2:$F$10003,($H12-1)*$L$2 + K$2) -> -0.92908267 | L12: =INDEX(Random!$F$2:$F$10003,($H12-1)*$L$2 + L$2) -> -1.1724312 | M12: {=TRANSPOSE(MMULT($B$28:$E$31, TRANSPOSE(I12:L12)))} -> 1.6344115 | N12: -0.03824767 | O12: 0.022734953 | P12: -0.53456855 | Q12: =$B$7 * EXP(($F$11 - $F$7 - $C$7*$C$7/2)*$C$3 + M12*$C$7*SQRT($C$3)) -> 1.242041 | R12: =$B$8 * EXP(($F$11 - $F$8 - $C$8*$C$8/2)*$C$3 + N12*$C$8*SQRT($C$3)) -> 1.3482671 | S12: =$B$9 * EXP(($F$11 - $F$9 - $C$9*$C$9/2)*$C$3 + O12*$C$9*SQRT($C$3)) -> 0.0063106791 | T12: =$B$10 * EXP(($F$11 - $F$10 - $C$10*$C$10/2)*$C$3 + P12*$C$10*SQRT($C$3)) -> 0.71641683 | U12: =Q12/$B$7 -> 1.0570562 | V12: =R12/$B$8 -> 0.99797713 | W12: =S12/$B$9 -> 1.0080957 | X12: =T12/$B$10 -> 0.99089465 | Y12: =$C$4 * (MAX(MAX(U12:X12) - $C$2, 0)) -> 57.056161
A13: Cross Volatility | H13: 11 | I13: =INDEX(Random!$F$2:$F$10003,($H13-1)*$L$2 + I$2) -> -0.72345226 | J13: =INDEX(Random!$F$2:$F$10003,($H13-1)*$L$2 + J$2) -> -0.66277608 | K13: =INDEX(Random!$F$2:$F$10003,($H13-1)*$L$2 + K$2) -> -1.0884108 | L13: =INDEX(Random!$F$2:$F$10003,($H13-1)*$L$2 + L$2) -> -0.29335385 | M13: {=TRANSPOSE(MMULT($B$28:$E$31, TRANSPOSE(I13:L13)))} -> -0.72345226 | N13: -0.97841315 | O13: -1.3440212 | P13: -0.76679126 | Q13: =$B$7 * EXP(($F$11 - $F$7 - $C$7*$C$7/2)*$C$3 + M13*$C$7*SQRT($C$3)) -> 1.1531338 | R13: =$B$8 * EXP(($F$11 - $F$8 - $C$8*$C$8/2)*$C$3 + N13*$C$8*SQRT($C$3)) -> 1.3033973 | S13: =$B$9 * EXP(($F$11 - $F$9 - $C$9*$C$9/2)*$C$3 + O13*$C$9*SQRT($C$3)) -> 0.0059545531 | T13: =$B$10 * EXP(($F$11 - $F$10 - $C$10*$C$10/2)*$C$3 + P13*$C$10*SQRT($C$3)) -> 0.71235238 | U13: =Q13/$B$7 -> 0.98139046 | V13: =R13/$B$8 -> 0.96476486 | W13: =S13/$B$9 -> 0.95120657 | X13: =T13/$B$10 -> 0.98527301 | Y13: =$C$4 * (MAX(MAX(U13:X13) - $C$2, 0)) -> 0
A14: Ccy | B14: EUR | C14: GBP | D14: JPY | H14: 12 | I14: =INDEX(Random!$F$2:$F$10003,($H14-1)*$L$2 + I$2) -> -0.59961662 | J14: =INDEX(Random!$F$2:$F$10003,($H14-1)*$L$2 + J$2) -> 0.35744114 | K14: =INDEX(Random!$F$2:$F$10003,($H14-1)*$L$2 + K$2) -> -1.5645362 | L14: =INDEX(Random!$F$2:$F$10003,($H14-1)*$L$2 + L$2) -> 0.12103896 | M14: {=TRANSPOSE(MMULT($B$28:$E$31, TRANSPOSE(I14:L14)))} -> -0.59961662 | N14: -0.25001798 | O14: -1.6067949 | P14: -0.12960659 | Q14: =$B$7 * EXP(($F$11 - $F$7 - $C$7*$C$7/2)*$C$3 + M14*$C$7*SQRT($C$3)) -> 1.1576408 | R14: =$B$8 * EXP(($F$11 - $F$8 - $C$8*$C$8/2)*$C$3 + N14*$C$8*SQRT($C$3)) -> 1.3380274 | S14: =$B$9 * EXP(($F$11 - $F$9 - $C$9*$C$9/2)*$C$3 + O14*$C$9*SQRT($C$3)) -> 0.0058884233 | T14: =$B$10 * EXP(($F$11 - $F$10 - $C$10*$C$10/2)*$C$3 + P14*$C$10*SQRT($C$3)) -> 0.72356019 | U14: =Q14/$B$7 -> 0.98522617 | V14: =R14/$B$8 -> 0.99039775 | W14: =S14/$B$9 -> 0.94064271 | X14: =T14/$B$10 -> 1.0007748 | Y14: =$C$4 * (MAX(MAX(U14:X14) - $C$2, 0)) -> 0.77481366
A15: GBP | B15: 0.045 | H15: 13 | I15: =INDEX(Random!$F$2:$F$10003,($H15-1)*$L$2 + I$2) -> 0.55255032 | J15: =INDEX(Random!$F$2:$F$10003,($H15-1)*$L$2 + J$2) -> 0.30477959 | K15: =INDEX(Random!$F$2:$F$10003,($H15-1)*$L$2 + K$2) -> -1.122036 | L15: =INDEX(Random!$F$2:$F$10003,($H15-1)*$L$2 + L$2) -> 0.88318593 | M15: {=TRANSPOSE(MMULT($B$28:$E$31, TRANSPOSE(I15:L15)))} -> 0.55255032 | N15: 0.62268016 | O15: -0.59807548 | P15: 1.0952093 | Q15: =$B$7 * EXP(($F$11 - $F$7 - $C$7*$C$7/2)*$C$3 + M15*$C$7*SQRT($C$3)) -> 1.200427 | R15: =$B$8 * EXP(($F$11 - $F$8 - $C$8*$C$8/2)*$C$3 + N15*$C$8*SQRT($C$3)) -> 1.3807317 | S15: =$B$9 * EXP(($F$11 - $F$9 - $C$9*$C$9/2)*$C$3 + O15*$C$9*SQRT($C$3)) -> 0.0061463527 | T15: =$B$10 * EXP(($F$11 - $F$10 - $C$10*$C$10/2)*$C$3 + P15*$C$10*SQRT($C$3)) -> 0.74560183 | U15: =Q15/$B$7 -> 1.02164 | V15: =R15/$B$8 -> 1.0220071 | W15: =S15/$B$9 -> 0.98184548 | X15: =T15/$B$10 -> 1.0312612 | Y15: =$C$4 * (MAX(MAX(U15:X15) - $C$2, 0)) -> 31.261182
A16: JPY | B16: 0.072 | C16: 0.081 | H16: 14 | I16: =INDEX(Random!$F$2:$F$10003,($H16-1)*$L$2 + I$2) -> 0.35417352 | J16: =INDEX(Random!$F$2:$F$10003,($H16-1)*$L$2 + J$2) -> 2.4464606 | K16: =INDEX(Random!$F$2:$F$10003,($H16-1)*$L$2 + K$2) -> 0.86114115 | L16: =INDEX(Random!$F$2:$F$10003,($H16-1)*$L$2 + L$2) -> -0.19836295 | M16: {=TRANSPOSE(MMULT($B$28:$E$31, TRANSPOSE(I16:L16)))} -> 0.35417352 | N16: 1.7916342 | O16: 1.0554808 | P16: 0.57199607 | Q16: =$B$7 * EXP(($F$11 - $F$7 - $C$7*$C$7/2)*$C$3 + M16*$C$7*SQRT($C$3)) -> 1.1929491 | R16: =$B$8 * EXP(($F$11 - $F$8 - $C$8*$C$8/2)*$C$3 + N16*$C$8*SQRT($C$3)) -> 1.440076 | S16: =$B$9 * EXP(($F$11 - $F$9 - $C$9*$C$9/2)*$C$3 + O16*$C$9*SQRT($C$3)) -> 0.0065938341 | T16: =$B$10 * EXP(($F$11 - $F$10 - $C$10*$C$10/2)*$C$3 + P16*$C$10*SQRT($C$3)) -> 0.73610517 | U16: =Q16/$B$7 -> 1.0152758 | V16: =R16/$B$8 -> 1.0659334 | W16: =S16/$B$9 -> 1.0533281 | X16: =T16/$B$10 -> 1.0181261 | Y16: =$C$4 * (MAX(MAX(U16:X16) - $C$2, 0)) -> 65.933384
